Workbook

Sheet BTA
A1: HISSE | E1: DOLAŞIM | F1: PİYASA | G1: LOT.S | H1: ANLIK | J1: KAR-ZARAR | X1: PAZAR
A2: ANA PAZAR | Q2: BTA | R2: UCUZ KALANLAR | S2: KOPYASI | T2: AL_SAT | U2: MARTI +21,39 | V2: =IFERROR(VLOOKUP(LEFT(U3,FIND(" ",U3)-1),'BTA Tarama'!$A:$K,11,0),"") | X2: =IF(COUNTIF('Yıldız Liste'!A:A, A2)>0, "Yıldız Pazar", IF(COUNTIF('Ana Pazar Liste'!A:A, A2)>0, "Ana Pazar", IF(COUNTIF('Alt Pazar Liste'!A:A, A2)>0, "Alt Pazar", "")))
A3: RAYSG | B3: Sigorta Sirketleri | C3: 9346162322 | D3: 163069855 | E3: =VLOOKUP(A3,'Tüm - Sektör'!$A:$H,5,0) -> 0 | F3: =VLOOKUP(A3,'Tüm - Sektör'!$A:$H,6,0) -> 0 | G3: =VLOOKUP(A3,'Tüm - Sektör'!$A:$H,7,0) -> 8.970337 | H3: 156.3 | I3: =VLOOKUP(A3,'Tüm - Sektör'!$A:$H,9,0) -> #REF! | J3: =VLOOKUP(A3,'Tüm - Sektör'!$A:$H,10,0) -> #REF! | K3: =VLOOKUP(A3,'Tüm - Sektör'!$A:$H,11,0) -> #REF! | L3: =VLOOKUP(A3,'Tüm - Sektör'!$A:$H,12,0) -> #REF! | M3: =VLOOKUP(A3,'Tüm - Sektör'!$A:$H,13,0) -> #REF! | N3: =VLOOKUP(A3,'Tüm - Sektör'!$A:$H,14,0) -> #REF! | O3: =VLOOKUP(A3,'Tüm - Sektör'!$A:$H,15,0) -> #REF! | P3: =VLOOKUP(A3,'Tüm - Sektör'!$A:$H,16,0) -> #REF! | Q3: =E3*G3/100 -> 0 | R3: =IF(OR(H3="", H4="", Q3=0), "", IF(H3<H4, (H4-H3)/H3, "")) | S3: 0 | T3: =S3-Q3 -> 0 | U3: YYAPI +12,50 | V3: =IFERROR(VLOOKUP(LEFT(U4,FIND(" ",U4)-1),'BTA Tarama'!$A:$K,11,0),"") -> 23629322496 | W3: BJKAS [AL] | X3: =IF(COUNTIF('Yıldız Liste'!A:A, A3)>0, "Yıldız Pazar", IF(COUNTIF('Ana Pazar Liste'!A:A, A3)>0, "Ana Pazar", IF(COUNTIF('Alt Pazar Liste'!A:A, A3)>0, "Alt Pazar", ""))) -> Ana Pazar
A4: ZEDUR | B4: Perakende Ticaret | C4: 1357332842 | D4: 535000000 | E4: =VLOOKUP(A4,'Tüm - Sektör'!$A:$H,5,0) -> 0 | F4: =VLOOKUP(A4,'Tüm - Sektör'!$A:$H,6,0) -> 0 | G4: =VLOOKUP(A4,'Tüm - Sektör'!$A:$H,7,0) -> 0 | H4: 7.64 | I4: =VLOOKUP(A4,'Tüm - Sektör'!$A:$H,9,0) -> #REF! | J4: =VLOOKUP(A4,'Tüm - Sektör'!$A:$H,10,0) -> #REF! | K4: =VLOOKUP(A4,'Tüm - Sektör'!$A:$H,11,0) -> #REF! | L4: =VLOOKUP(A4,'Tüm - Sektör'!$A:$H,12,0) -> #REF! | M4: =VLOOKUP(A4,'Tüm - Sektör'!$A:$H,13,0) -> #REF! | N4: =VLOOKUP(A4,'Tüm - Sektör'!$A:$H,14,0) -> #REF! | O4: =VLOOKUP(A4,'Tüm - Sektör'!$A:$H,15,0) -> #REF! | P4: =VLOOKUP(A4,'Tüm - Sektör'!$A:$H,16,0) -> #REF! | Q4: =E4*G4/100 -> 0 | R4: =IF(OR(H4="", H5="", Q4=0), "", IF(H4<H5, (H5-H4)/H4, "")) | S4: 0 | T4: 0 | U4: SKTAS +9,16 | V4: =IFERROR(VLOOKUP(LEFT(U5,FIND(" ",U5)-1),'BTA Tarama'!$A:$K,11,0),"") -> -5036006542 | X4: =IF(COUNTIF('Yıldız Liste'!A:A, A4)>0, "Yıldız Pazar", IF(COUNTIF('Ana Pazar Liste'!A:A, A4)>0, "Ana Pazar", IF(COUNTIF('Alt Pazar Liste'!A:A, A4)>0, "Alt Pazar", ""))) -> Ana Pazar
A5: DOCO | B5: Yiyecek ve İçecek Hizmetleri | C5: 24553432694 | D5: 10983458 | E5: =VLOOKUP(A5,'Tüm - Sektör'!$A:$H,5,0) -> 0.37512759 | F5: =VLOOKUP(A5,'Tüm - Sektör'!$A:$H,6,0) -> 0.0029423967 | G5: =VLOOKUP(A5,'Tüm - Sektör'!$A:$H,7,0) -> 0.000348717 | H5: 11290 | I5: =VLOOKUP(A5,'Tüm - Sektör'!$A:$H,9,0) -> #REF! | J5: =VLOOKUP(A5,'Tüm - Sektör'!$A:$H,10,0) -> #REF! | K5: =VLOOKUP(A5,'Tüm - Sektör'!$A:$H,11,0) -> #REF! | L5: =VLOOKUP(A5,'Tüm - Sektör'!$A:$H,12,0) -> #REF! | M5: =VLOOKUP(A5,'Tüm - Sektör'!$A:$H,13,0) -> #REF! | N5: =VLOOKUP(A5,'Tüm - Sektör'!$A:$H,14,0) -> #REF! | O5: =VLOOKUP(A5,'Tüm - Sektör'!$A:$H,15,0) -> #REF! | P5: =VLOOKUP(A5,'Tüm - Sektör'!$A:$H,16,0) -> #REF! | Q5: =E5*G5/100 -> 1.3081337e-06 | R5: =IF(OR(H5="", H6="", Q5=0), "", IF(H5<H6, (H6-H5)/H5, "")) | S5: 1.2955113e-06 | T5: =S5-Q5 -> -1.2622343e-08 | U5: NIBAS +8,84 | V5: =IFERROR(VLOOKUP(LEFT(U6,FIND(" ",U6)-1),'BTA Tarama'!$A:$K,11,0),"") -> -13127054845 | X5: =IF(COUNTIF('Yıldız Liste'!A:A, A5)>0, "Yıldız Pazar", IF(COUNTIF('Ana Pazar Liste'!A:A, A5)>0, "Ana Pazar", IF(COUNTIF('Alt Pazar Liste'!A:A, A5)>0, "Alt Pazar", ""))) -> Ana Pazar
A6: LYDYE | B6: Gıda , İçecek ve Tütün | C6: 3279541734 | D6: 1891069 | E6: =VLOOKUP(A6,'Tüm - Sektör'!$A:$H,5,0) -> 5.9415793 | F6: =VLOOKUP(A6,'Tüm - Sektör'!$A:$H,6,0) -> 0.25523266 | G6: =VLOOKUP(A6,'Tüm - Sektör'!$A:$H,7,0) -> 0.000607739 | H6: 11080 | I6: =VLOOKUP(A6,'Tüm - Sektör'!$A:$H,9,0) -> #REF! | J6: =VLOOKUP(A6,'Tüm - Sektör'!$A:$H,10,0) -> #REF! | K6: =VLOOKUP(A6,'Tüm - Sektör'!$A:$H,11,0) -> #REF! | L6: =VLOOKUP(A6,'Tüm - Sektör'!$A:$H,12,0) -> #REF! | M6: =VLOOKUP(A6,'Tüm - Sektör'!$A:$H,13,0) -> #REF! | N6: =VLOOKUP(A6,'Tüm - Sektör'!$A:$H,14,0) -> #REF! | O6: =VLOOKUP(A6,'Tüm - Sektör'!$A:$H,15,0) -> #REF! | P6: =VLOOKUP(A6,'Tüm - Sektör'!$A:$H,16,0) -> #REF! | Q6: =E6*G6/100 -> 3.6109295e-05 | R6: =IF(OR(H6="", H7="", Q6=0), "", IF(H6<H7, (H7-H6)/H6, "")) | S6: 3.3313155e-05 | T6: =S6-Q6 -> -2.7961402e-06 | U6: MEKAG +5,72 | V6: =IFERROR(VLOOKUP(LEFT(U7,FIND(" ",U7)-1),'BTA Tarama'!$A:$K,11,0),"") | X6: =IF(COUNTIF('Yıldız Liste'!A:A, A6)>0, "Yıldız Pazar", IF(COUNTIF('Ana Pazar Liste'!A:A, A6)>0, "Ana Pazar", IF(COUNTIF('Alt Pazar Liste'!A:A, A6)>0, "Alt Pazar", ""))) -> Ana Pazar
A7: MRSHL | B7: Kimya , İlaç , Petrol , Lastik ve Plastik Ürünler | C7: 1138168471 | D7: 10994134 | E7: =VLOOKUP(A7,'Tüm - Sektör'!$A:$H,5,0) -> 36.035476 | F7: =VLOOKUP(A7,'Tüm - Sektör'!$A:$H,6,0) -> 2.0270255 | G7: =VLOOKUP(A7,'Tüm - Sektör'!$A:$H,7,0) -> 0.000701302 | H7: 1585 | I7: =VLOOKUP(A7,'Tüm - Sektör'!$A:$H,9,0) -> #REF! | J7: =VLOOKUP(A7,'Tüm - Sektör'!$A:$H,10,0) -> #REF! | K7: =VLOOKUP(A7,'Tüm - Sektör'!$A:$H,11,0) -> #REF! | L7: =VLOOKUP(A7,'Tüm - Sektör'!$A:$H,12,0) -> #REF! | M7: =VLOOKUP(A7,'Tüm - Sektör'!$A:$H,13,0) -> #REF! | N7: =VLOOKUP(A7,'Tüm - Sektör'!$A:$H,14,0) -> #REF! | O7: =VLOOKUP(A7,'Tüm - Sektör'!$A:$H,15,0) -> #REF! | P7: =VLOOKUP(A7,'Tüm - Sektör'!$A:$H,16,0) -> #REF! | Q7: =E7*G7/100 -> 0.00025271752 | R7: =IF(OR(H7="", H8="", Q7=0), "", IF(H7<H8, (H8-H7)/H7, "")) | S7: 0.0002448394 | T7: =S7-Q7 -> -7.8781133e-06 | U7: HUBVC +5,25 | V7: =IFERROR(VLOOKUP(LEFT(U8,FIND(" ",U8)-1),'BTA Tarama'!$A:$K,11,0),"") -> -5270320944 | X7: =IF(COUNTIF('Yıldız Liste'!A:A, A7)>0, "Yıldız Pazar", IF(COUNTIF('Ana Pazar Liste'!A:A, A7)>0, "Ana Pazar", IF(COUNTIF('Alt Pazar Liste'!A:A, A7)>0, "Alt Pazar", ""))) -> Ana Pazar
A8: CMBTN | B8: Tas ve Toprağa Dayalı | C8: 238701401 | D8: 1770000 | E8: =VLOOKUP(A8,'Tüm - Sektör'!$A:$H,5,0) -> 30.234624 | F8: =VLOOKUP(A8,'Tüm - Sektör'!$A:$H,6,0) -> 10.977962 | G8: =VLOOKUP(A8,'Tüm - Sektör'!$A:$H,7,0) -> 0.000876247 | H8: 1510 | I8: =VLOOKUP(A8,'Tüm - Sektör'!$A:$H,9,0) -> #REF! | J8: =VLOOKUP(A8,'Tüm - Sektör'!$A:$H,10,0) -> #REF! | K8: =VLOOKUP(A8,'Tüm - Sektör'!$A:$H,11,0) -> #REF! | L8: =VLOOKUP(A8,'Tüm - Sektör'!$A:$H,12,0) -> #REF! | M8: =VLOOKUP(A8,'Tüm - Sektör'!$A:$H,13,0) -> #REF! | N8: =VLOOKUP(A8,'Tüm - Sektör'!$A:$H,14,0) -> #REF! | O8: =VLOOKUP(A8,'Tüm - Sektör'!$A:$H,15,0) -> #REF! | P8: =VLOOKUP(A8,'Tüm - Sektör'!$A:$H,16,0) -> #REF! | Q8: =E8*G8/100 -> 0.00026492999 | R8: =IF(OR(H8="", H9="", Q8=0), "", IF(H8<H9, (H9-H8)/H8, "")) -> 0.056291391 | S8: 0.00025892834 | T8: =S8-Q8 -> -6.0016503e-06 | U8: HDFGS +4,57 | V8: =IFERROR(VLOOKUP(LEFT(U9,FIND(" ",U9)-1),'BTA Tarama'!$A:$K,11,0),"") | X8: =IF(COUNTIF('Yıldız Liste'!A:A, A8)>0, "Yıldız Pazar", IF(COUNTIF('Ana Pazar Liste'!A:A, A8)>0, "Ana Pazar", IF(COUNTIF('Alt Pazar Liste'!A:A, A8)>0, "Alt Pazar", ""))) -> Ana Pazar
A9: UFUK | B9: Holdingler ve Yatırım Sirketleri | C9: 2686991410 | D9: 46846881 | E9: =VLOOKUP(A9,'Tüm - Sektör'!$A:$H,5,0) -> 1.4808474 | F9: =VLOOKUP(A9,'Tüm - Sektör'!$A:$H,6,0) -> 0.018063071 | G9: =VLOOKUP(A9,'Tüm - Sektör'!$A:$H,7,0) -> 16.937048 | H9: 1595 | I9: =VLOOKUP(A9,'Tüm - Sektör'!$A:$H,9,0) -> #REF! | J9: =VLOOKUP(A9,'Tüm - Sektör'!$A:$H,10,0) -> #REF! | K9: =VLOOKUP(A9,'Tüm - Sektör'!$A:$H,11,0) -> #REF! | L9: =VLOOKUP(A9,'Tüm - Sektör'!$A:$H,12,0) -> #REF! | M9: =VLOOKUP(A9,'Tüm - Sektör'!$A:$H,13,0) -> #REF! | N9: =VLOOKUP(A9,'Tüm - Sektör'!$A:$H,14,0) -> #REF! | O9: =VLOOKUP(A9,'Tüm - Sektör'!$A:$H,15,0) -> #REF! | P9: =VLOOKUP(A9,'Tüm - Sektör'!$A:$H,16,0) -> #REF! | Q9: =E9*G9/100 -> 0.25081184 | R9: =IF(OR(H9="", H10="", Q9=0), "", IF(H9<H10, (H10-H9)/H9, "")) | S9: 0.24724653 | T9: =S9-Q9 -> -0.0035653105 | U9: PAHOL +4,52 | V9: =IFERROR(VLOOKUP(LEFT(U10,FIND(" ",U10)-1),'BTA Tarama'!$A:$K,11,0),"") -> -88119388752 | X9: =IF(COUNTIF('Yıldız Liste'!A:A, A9)>0, "Yıldız Pazar", IF(COUNTIF('Ana Pazar Liste'!A:A, A9)>0, "Ana Pazar", IF(COUNTIF('Alt Pazar Liste'!A:A, A9)>0, "Alt Pazar", ""))) -> Ana Pazar
A10: GUNDG | B10: Gıda , İçecek ve Tütün | C10: 832617284 | D10: 39000000 | E10: =VLOOKUP(A10,'Tüm - Sektör'!$A:$H,5,0) -> 2.6117673 | F10: =VLOOKUP(A10,'Tüm - Sektör'!$A:$H,6,0) -> 0.039393172 | G10: =VLOOKUP(A10,'Tüm - Sektör'!$A:$H,7,0) -> 10.211128 | H10: 1500 | I10: =VLOOKUP(A10,'Tüm - Sektör'!$A:$H,9,0) -> #REF! | J10: =VLOOKUP(A10,'Tüm - Sektör'!$A:$H,10,0) -> #REF! | K10: =VLOOKUP(A10,'Tüm - Sektör'!$A:$H,11,0) -> #REF! | L10: =VLOOKUP(A10,'Tüm - Sektör'!$A:$H,12,0) -> #REF! | M10: =VLOOKUP(A10,'Tüm - Sektör'!$A:$H,13,0) -> #REF! | N10: =VLOOKUP(A10,'Tüm - Sektör'!$A:$H,14,0) -> #REF! | O10: =VLOOKUP(A10,'Tüm - Sektör'!$A:$H,15,0) -> #REF! | P10: =VLOOKUP(A10,'Tüm - Sektör'!$A:$H,16,0) -> #REF! | Q10: =E10*G10/100 -> 0.2666909 | R10: =IF(OR(H10="", H11="", Q10=0), "", IF(H10<H11, (H11-H10)/H10, "")) | S10: 0.24011786 | T10: =S10-Q10 -> -0.026573043 | U10: VRGYO +3,68 | V10: =IFERROR(VLOOKUP(LEFT(U11,FIND(" ",U11)-1),'BTA Tarama'!$A:$K,11,0),"") | X10: =IF(COUNTIF('Yıldız Liste'!A:A, A10)>0, "Yıldız Pazar", IF(COUNTIF('Ana Pazar Liste'!A:A, A10)>0, "Ana Pazar", IF(COUNTIF('Alt Pazar Liste'!A:A, A10)>0, "Alt Pazar", ""))) -> Ana Pazar
A11: MAALT | B11: Oteller ve Lokantalar | C11: 5369083553 | D11: 8640048 | E11: =VLOOKUP(A11,'Tüm - Sektör'!$A:$H,5,0) -> 24.333294 | F11: =VLOOKUP(A11,'Tüm - Sektör'!$A:$H,6,0) -> 2.5603071 | G11: =VLOOKUP(A11,'Tüm - Sektör'!$A:$H,7,0) -> 1.637903 | H11: 1004 | I11: =VLOOKUP(A11,'Tüm - Sektör'!$A:$H,9,0) -> #REF! | J11: =VLOOKUP(A11,'Tüm - Sektör'!$A:$H,10,0) -> #REF! | K11: =VLOOKUP(A11,'Tüm - Sektör'!$A:$H,11,0) -> #REF! | L11: =VLOOKUP(A11,'Tüm - Sektör'!$A:$H,12,0) -> #REF! | M11: =VLOOKUP(A11,'Tüm - Sektör'!$A:$H,13,0) -> #REF! | N11: =VLOOKUP(A11,'Tüm - Sektör'!$A:$H,14,0) -> #REF! | O11: =VLOOKUP(A11,'Tüm - Sektör'!$A:$H,15,0) -> #REF! | P11: =VLOOKUP(A11,'Tüm - Sektör'!$A:$H,16,0) -> #REF! | Q11: =E11*G11/100 -> 0.39855576 | R11: =IF(OR(H11="", H12="", Q11=0), "", IF(H11<H12, (H12-H11)/H11, "")) | S11: 0.39307464 | T11: =S11-Q11 -> -0.0054811204 | U11: SEKUR +3,64 | V11: =IFERROR(VLOOKUP(LEFT(U12,FIND(" ",U12)-1),'BTA Tarama'!$A:$K,11,0),"") | X11: =IF(COUNTIF('Yıldız Liste'!A:A, A11)>0, "Yıldız Pazar", IF(COUNTIF('Ana Pazar Liste'!A:A, A11)>0, "Ana Pazar", IF(COUNTIF('Alt Pazar Liste'!A:A, A11)>0, "Alt Pazar", ""))) -> Ana Pazar
A12: VERUS | B12: Holdingler ve Yatırım Sirketleri | C12: 4697773484 | D12: 70000000 | E12: =VLOOKUP(A12,'Tüm - Sektör'!$A:$H,5,0) -> 3.9819918 | F12: =VLOOKUP(A12,'Tüm - Sektör'!$A:$H,6,0) -> 0.081732181 | G12: =VLOOKUP(A12,'Tüm - Sektör'!$A:$H,7,0) -> 14.69279 | H12: 684 | I12: =VLOOKUP(A12,'Tüm - Sektör'!$A:$H,9,0) -> #REF! | J12: =VLOOKUP(A12,'Tüm - Sektör'!$A:$H,10,0) -> #REF! | K12: =VLOOKUP(A12,'Tüm - Sektör'!$A:$H,11,0) -> #REF! | L12: =VLOOKUP(A12,'Tüm - Sektör'!$A:$H,12,0) -> #REF! | M12: =VLOOKUP(A12,'Tüm - Sektör'!$A:$H,13,0) -> #REF! | N12: =VLOOKUP(A12,'Tüm - Sektör'!$A:$H,14,0) -> #REF! | O12: =VLOOKUP(A12,'Tüm - Sektör'!$A:$H,15,0) -> #REF! | P12: =VLOOKUP(A12,'Tüm - Sektör'!$A:$H,16,0) -> #REF! | Q12: =E12*G12/100 -> 0.5850657 | R12: =IF(OR(H12="", H13="", Q12=0), "", IF(H12<H13, (H13-H12)/H12, "")) | S12: 0.59729095 | T12: =S12-Q12 -> 0.012225253 | U12: BJKAS +3,22 | V12: =IFERROR(VLOOKUP(LEFT(U13,FIND(" ",U13)-1),'BTA Tarama'!$A:$K,11,0),"") -> -331639009215 | X12: =IF(COUNTIF('Yıldız Liste'!A:A, A12)>0, "Yıldız Pazar", IF(COUNTIF('Ana Pazar Liste'!A:A, A12)>0, "Ana Pazar", IF(COUNTIF('Alt Pazar Liste'!A:A, A12)>0, "Alt Pazar", ""))) -> Ana Pazar
A13: ALCAR | B13: Metal Esya,Makine,Elektrikli Cihazlar,Ulasım Araç | C13: 2033187111 | D13: 10800000 | E13: =VLOOKUP(A13,'Tüm - Sektör'!$A:$H,5,0) -> 34.714954 | F13: =VLOOKUP(A13,'Tüm - Sektör'!$A:$H,6,0) -> 4.6249605 | G13: =VLOOKUP(A13,'Tüm - Sektör'!$A:$H,7,0) -> 1.717981 | H13: 671 | I13: =VLOOKUP(A13,'Tüm - Sektör'!$A:$H,9,0) -> #REF! | J13: =VLOOKUP(A13,'Tüm - Sektör'!$A:$H,10,0) -> #REF! | K13: =VLOOKUP(A13,'Tüm - Sektör'!$A:$H,11,0) -> #REF! | L13: =VLOOKUP(A13,'Tüm - Sektör'!$A:$H,12,0) -> #REF! | M13: =VLOOKUP(A13,'Tüm - Sektör'!$A:$H,13,0) -> #REF! | N13: =VLOOKUP(A13,'Tüm - Sektör'!$A:$H,14,0) -> #REF! | O13: =VLOOKUP(A13,'Tüm - Sektör'!$A:$H,15,0) -> #REF! | P13: =VLOOKUP(A13,'Tüm - Sektör'!$A:$H,16,0) -> #REF! | Q13: =E13*G13/100 -> 0.59639631 | R13: =IF(OR(H13="", H14="", Q13=0), "", IF(H13<H14, (H14-H13)/H13, "")) | S13: 0.58677701 | T13: =S13-Q13 -> -0.0096192953 | U13: HURGZ +3,07 | V13: =IFERROR(VLOOKUP(LEFT(U14,FIND(" ",U14)-1),'BTA Tarama'!$A:$K,11,0),"") -> -1062033326 | X13: =IF(COUNTIF('Yıldız Liste'!A:A, A13)>0, "Yıldız Pazar", IF(COUNTIF('Ana Pazar Liste'!A:A, A13)>0, "Ana Pazar", IF(COUNTIF('Alt Pazar Liste'!A:A, A13)>0, "Alt Pazar", ""))) -> Ana Pazar
A14: AYCES | B14: Oteller ve Lokantalar | C14: 5221598542 | D14: 25000000 | E14: =VLOOKUP(A14,'Tüm - Sektör'!$A:$H,5,0) -> 47.677261 | F14: =VLOOKUP(A14,'Tüm - Sektör'!$A:$H,6,0) -> 4.0149272 | G14: =VLOOKUP(A14,'Tüm - Sektör'!$A:$H,7,0) -> 1.868281 | H14: 449.25 | I14: =VLOOKUP(A14,'Tüm - Sektör'!$A:$H,9,0) -> #REF! | J14: =VLOOKUP(A14,'Tüm - Sektör'!$A:$H,10,0) -> #REF! | K14: =VLOOKUP(A14,'Tüm - Sektör'!$A:$H,11,0) -> #REF! | L14: =VLOOKUP(A14,'Tüm - Sektör'!$A:$H,12,0) -> #REF! | M14: =VLOOKUP(A14,'Tüm - Sektör'!$A:$H,13,0) -> #REF! | N14: =VLOOKUP(A14,'Tüm - Sektör'!$A:$H,14,0) -> #REF! | O14: =VLOOKUP(A14,'Tüm - Sektör'!$A:$H,15,0) -> #REF! | P14: =VLOOKUP(A14,'Tüm - Sektör'!$A:$H,16,0) -> #REF! | Q14: =E14*G14/100 -> 0.8907452 | R14: =IF(OR(H14="", H15="", Q14=0), "", IF(H14<H15, (H15-H14)/H14, "")) | S14: 0.89124116 | T14: =S14-Q14 -> 0.00049596058 | U14: YESIL +3,00 | V14: =IFERROR(VLOOKUP(LEFT(U15,FIND(" ",U15)-1),'BTA Tarama'!$A:$K,11,0),"") -> 1844737,6 | X14: =IF(COUNTIF('Yıldız Liste'!A:A, A14)>0, "Yıldız Pazar", IF(COUNTIF('Ana Pazar Liste'!A:A, A14)>0, "Ana Pazar", IF(COUNTIF('Alt Pazar Liste'!A:A, A14)>0, "Alt Pazar", ""))) -> Ana Pazar
A15: ALKLC | B15: Gıda , İçecek ve Tütün | C15: 2863294706 | D15: 112000000 | E15: =VLOOKUP(A15,'Tüm - Sektör'!$A:$H,5,0) -> 2.1083946 | F15: =VLOOKUP(A15,'Tüm - Sektör'!$A:$H,6,0) -> 0.044086538 | G15: =VLOOKUP(A15,'Tüm - Sektör'!$A:$H,7,0) -> 44.440303 | H15: 427 | I15: =VLOOKUP(A15,'Tüm - Sektör'!$A:$H,9,0) -> #REF! | J15: =VLOOKUP(A15,'Tüm - Sektör'!$A:$H,10,0) -> #REF! | K15: =VLOOKUP(A15,'Tüm - Sektör'!$A:$H,11,0) -> #REF! | L15: =VLOOKUP(A15,'Tüm - Sektör'!$A:$H,12,0) -> #REF! | M15: =VLOOKUP(A15,'Tüm - Sektör'!$A:$H,13,0) -> #REF! | N15: =VLOOKUP(A15,'Tüm - Sektör'!$A:$H,14,0) -> #REF! | O15: =VLOOKUP(A15,'Tüm - Sektör'!$A:$H,15,0) -> #REF! | P15: =VLOOKUP(A15,'Tüm - Sektör'!$A:$H,16,0) -> #REF! | Q15: =E15*G15/100 -> 0.93697694 | R15: =IF(OR(H15="", H16="", Q15=0), "", IF(H15<H16, (H16-H15)/H15, "")) | S15: 0.9397279 | T15: =S15-Q15 -> 0.0027509599 | U15: ULUFA +2,94 | V15: =IFERROR(VLOOKUP(LEFT(U16,FIND(" ",U16)-1),'BTA Tarama'!$A:$K,11,0),"") -> -173270325992 | X15: =IF(COUNTIF('Yıldız Liste'!A:A, A15)>0, "Yıldız Pazar", IF(COUNTIF('Ana Pazar Liste'!A:A, A15)>0, "Ana Pazar", IF(COUNTIF('Alt Pazar Liste'!A:A, A15)>0, "Alt Pazar", ""))) -> Ana Pazar
A16: KAPLM | B16: Kağıt, Kağıt Ürünleri Basım | C16: 1981884130 | D16: 20000000 | E16: =VLOOKUP(A16,'Tüm - Sektör'!$A:$H,5,0) -> 24.73508 | F16: =VLOOKUP(A16,'Tüm - Sektör'!$A:$H,6,0) -> 2.9031784 | G16: =VLOOKUP(A16,'Tüm - Sektör'!$A:$H,7,0) -> 3.966659 | H16: 407.75 | I16: =VLOOKUP(A16,'Tüm - Sektör'!$A:$H,9,0) -> #REF! | J16: =VLOOKUP(A16,'Tüm - Sektör'!$A:$H,10,0) -> #REF! | K16: =VLOOKUP(A16,'Tüm - Sektör'!$A:$H,11,0) -> #REF! | L16: =VLOOKUP(A16,'Tüm - Sektör'!$A:$H,12,0) -> #REF! | M16: =VLOOKUP(A16,'Tüm - Sektör'!$A:$H,13,0) -> #REF! | N16: =VLOOKUP(A16,'Tüm - Sektör'!$A:$H,14,0) -> #REF! | O16: =VLOOKUP(A16,'Tüm - Sektör'!$A:$H,15,0) -> #REF! | P16: =VLOOKUP(A16,'Tüm - Sektör'!$A:$H,16,0) -> #REF! | Q16: =E16*G16/100 -> 0.98115626 | R16: =IF(OR(H16="", H17="", Q16=0), "", IF(H16<H17, (H17-H16)/H16, "")) | S16: 0.9698581 | T16: =S16-Q16 -> -0.011298163 | U16: BORSK +2,45 | V16: =IFERROR(VLOOKUP(LEFT(U17,FIND(" ",U17)-1),'BTA Tarama'!$A:$K,11,0),"") | X16: =IF(COUNTIF('Yıldız Liste'!A:A, A16)>0, "Yıldız Pazar", IF(COUNTIF('Ana Pazar Liste'!A:A, A16)>0, "Ana Pazar", IF(COUNTIF('Alt Pazar Liste'!A:A, A16)>0, "Alt Pazar", ""))) -> Ana Pazar
... A61: GZNMI | B61: Girisim Sermayesi Yatırım Ortaklıkları | C61: 1357332842 | D61: 535000000 | E61: =VLOOKUP(A61,'Tüm - Sektör'!$A:$H,5,0) -> 25.310971 | F61: =VLOOKUP(A61,'Tüm - Sektör'!$A:$H,6,0) -> 6.4899925 | G61: =VLOOKUP(A61,'Tüm - Sektör'!$A:$H,7,0) -> 29.489986 | H61: 53.6 | I61: =VLOOKUP(A61,'Tüm - Sektör'!$A:$H,9,0) -> #REF! | J61: =VLOOKUP(A61,'Tüm - Sektör'!$A:$H,10,0) -> #REF! | K61: =VLOOKUP(A61,'Tüm - Sektör'!$A:$H,11,0) -> #REF! | L61: =VLOOKUP(A61,'Tüm - Sektör'!$A:$H,12,0) -> #REF! | M61: =VLOOKUP(A61,'Tüm - Sektör'!$A:$H,13,0) -> #REF! | N61: =VLOOKUP(A61,'Tüm - Sektör'!$A:$H,14,0) -> #REF! | O61: =VLOOKUP(A61,'Tüm - Sektör'!$A:$H,15,0) -> #REF! | P61: =VLOOKUP(A61,'Tüm - Sektör'!$A:$H,16,0) -> #REF! | Q61: =E61*G61/100 -> 7.4642017 | R61: =IF(OR(H61="", H62="", Q61=0), "", IF(H61<H62, (H62-H61)/H61, "")) | S61: 6.9579341 | T61: =S61-Q61 -> -0.50626759 | U61: PETKM +0,35 | V61: =IFERROR(VLOOKUP(LEFT(U62,FIND(" ",U62)-1),'BTA Tarama'!$A:$K,11,0),"") -> 16842297,92 | X61: =IF(COUNTIF('Yıldız Liste'!A:A, A61)>0, "Yıldız Pazar", IF(COUNTIF('Ana Pazar Liste'!A:A, A61)>0, "Ana Pazar", IF(COUNTIF('Alt Pazar Liste'!A:A, A61)>0, "Alt Pazar", ""))) -> Ana Pazar
A62: IHAAS | B62: Güvenlik ve Sorusturma | C62: 1357332842 | D62: 535000000 | E62: =VLOOKUP(A62,'Tüm - Sektör'!$A:$H,5,0) -> 13.7306 | F62: =VLOOKUP(A62,'Tüm - Sektör'!$A:$H,6,0) -> 1.5315783 | G62: =VLOOKUP(A62,'Tüm - Sektör'!$A:$H,7,0) -> 56.026117 | H62: 52 | I62: =VLOOKUP(A62,'Tüm - Sektör'!$A:$H,9,0) -> #REF! | J62: =VLOOKUP(A62,'Tüm - Sektör'!$A:$H,10,0) -> #REF! | K62: =VLOOKUP(A62,'Tüm - Sektör'!$A:$H,11,0) -> #REF! | L62: =VLOOKUP(A62,'Tüm - Sektör'!$A:$H,12,0) -> #REF! | M62: =VLOOKUP(A62,'Tüm - Sektör'!$A:$H,13,0) -> #REF! | N62: =VLOOKUP(A62,'Tüm - Sektör'!$A:$H,14,0) -> #REF! | O62: =VLOOKUP(A62,'Tüm - Sektör'!$A:$H,15,0) -> #REF! | P62: =VLOOKUP(A62,'Tüm - Sektör'!$A:$H,16,0) -> #REF! | Q62: =E62*G62/100 -> 7.6927219 | R62: =IF(OR(H62="", H63="", Q62=0), "", IF(H62<H63, (H63-H62)/H62, "")) | S62: 7.7001259 | T62: -0.027034419 | U62: RUBNS +0,34 | V62: =IFERROR(VLOOKUP(LEFT(U63,FIND(" ",U63)-1),'BTA Tarama'!$A:$K,11,0),"") | X62: =IF(COUNTIF('Yıldız Liste'!A:A, A62)>0, "Yıldız Pazar", IF(COUNTIF('Ana Pazar Liste'!A:A, A62)>0, "Ana Pazar", IF(COUNTIF('Alt Pazar Liste'!A:A, A62)>0, "Alt Pazar", ""))) -> Ana Pazar
A63: IZINV | B63: Tarım Ormancılık ve Balıkçılık | C63: 367547592 | D63: 17512456 | E63: =VLOOKUP(A63,'Tüm - Sektör'!$A:$H,5,0) -> 63.745587 | F63: =VLOOKUP(A63,'Tüm - Sektör'!$A:$H,6,0) -> 68.679512 | G63: =VLOOKUP(A63,'Tüm - Sektör'!$A:$H,7,0) -> 12.279838 | H63: 51.1 | I63: =VLOOKUP(A63,'Tüm - Sektör'!$A:$H,9,0) -> #REF! | J63: =VLOOKUP(A63,'Tüm - Sektör'!$A:$H,10,0) -> #REF! | K63: =VLOOKUP(A63,'Tüm - Sektör'!$A:$H,11,0) -> #REF! | L63: =VLOOKUP(A63,'Tüm - Sektör'!$A:$H,12,0) -> #REF! | M63: =VLOOKUP(A63,'Tüm - Sektör'!$A:$H,13,0) -> #REF! | N63: =VLOOKUP(A63,'Tüm - Sektör'!$A:$H,14,0) -> #REF! | O63: =VLOOKUP(A63,'Tüm - Sektör'!$A:$H,15,0) -> #REF! | P63: =VLOOKUP(A63,'Tüm - Sektör'!$A:$H,16,0) -> #REF! | Q63: =E63*G63/100 -> 7.8278549 | R63: =IF(OR(H63="", H64="", Q63=0), "", IF(H63<H64, (H64-H63)/H63, "")) | S63: 7.5758216 | T63: =S63-Q63 -> -0.25203321 | U63: BSOKE +0,33 | V63: =IFERROR(VLOOKUP(LEFT(U64,FIND(" ",U64)-1),'BTA Tarama'!$A:$K,11,0),"") | X63: =IF(COUNTIF('Yıldız Liste'!A:A, A63)>0, "Yıldız Pazar", IF(COUNTIF('Ana Pazar Liste'!A:A, A63)>0, "Ana Pazar", IF(COUNTIF('Alt Pazar Liste'!A:A, A63)>0, "Alt Pazar", ""))) -> Ana Pazar
A64: SEGMN | B64: Gıda , İçecek ve Tütün | C64: 5548282822 | D64: 179000000 | E64: =VLOOKUP(A64,'Tüm - Sektör'!$A:$H,5,0) -> 17.359043 | F64: =VLOOKUP(A64,'Tüm - Sektör'!$A:$H,6,0) -> 1.9015273 | G64: =VLOOKUP(A64,'Tüm - Sektör'!$A:$H,7,0) -> 47.254247 | H64: 48.78 | I64: =VLOOKUP(A64,'Tüm - Sektör'!$A:$H,9,0) -> #REF! | J64: =VLOOKUP(A64,'Tüm - Sektör'!$A:$H,10,0) -> #REF! | K64: =VLOOKUP(A64,'Tüm - Sektör'!$A:$H,11,0) -> #REF! | L64: =VLOOKUP(A64,'Tüm - Sektör'!$A:$H,12,0) -> #REF! | M64: =VLOOKUP(A64,'Tüm - Sektör'!$A:$H,13,0) -> #REF! | N64: =VLOOKUP(A64,'Tüm - Sektör'!$A:$H,14,0) -> #REF! | O64: =VLOOKUP(A64,'Tüm - Sektör'!$A:$H,15,0) -> #REF! | P64: =VLOOKUP(A64,'Tüm - Sektör'!$A:$H,16,0) -> #REF! | Q64: =E64*G64/100 -> 8.202885 | R64: =IF(OR(H64="", H65="", Q64=0), "", IF(H64<H65, (H65-H64)/H64, "")) | S64: 8.4062338 | T64: =S64-Q64 -> 0.20334883 | U64: VAKBN +0,32 | V64: =IFERROR(VLOOKUP(LEFT(U65,FIND(" ",U65)-1),'BTA Tarama'!$A:$K,11,0),"") -> -236584567625 | X64: =IF(COUNTIF('Yıldız Liste'!A:A, A64)>0, "Yıldız Pazar", IF(COUNTIF('Ana Pazar Liste'!A:A, A64)>0, "Ana Pazar", IF(COUNTIF('Alt Pazar Liste'!A:A, A64)>0, "Alt Pazar", ""))) -> Ana Pazar
A65: BMSTL | B65: Ana Metal Sanayi | C65: 1380911336 | D65: 150000000 | E65: =VLOOKUP(A65,'Tüm - Sektör'!$A:$H,5,0) -> 11.985228 | F65: =VLOOKUP(A65,'Tüm - Sektör'!$A:$H,6,0) -> 1.8581748 | G65: =VLOOKUP(A65,'Tüm - Sektör'!$A:$H,7,0) -> 74.740385 | H65: 44.66 | I65: =VLOOKUP(A65,'Tüm - Sektör'!$A:$H,9,0) -> #REF! | J65: =VLOOKUP(A65,'Tüm - Sektör'!$A:$H,10,0) -> #REF! | K65: =VLOOKUP(A65,'Tüm - Sektör'!$A:$H,11,0) -> #REF! | L65: =VLOOKUP(A65,'Tüm - Sektör'!$A:$H,12,0) -> #REF! | M65: =VLOOKUP(A65,'Tüm - Sektör'!$A:$H,13,0) -> #REF! | N65: =VLOOKUP(A65,'Tüm - Sektör'!$A:$H,14,0) -> #REF! | O65: =VLOOKUP(A65,'Tüm - Sektör'!$A:$H,15,0) -> #REF! | P65: =VLOOKUP(A65,'Tüm - Sektör'!$A:$H,16,0) -> #REF! | Q65: =E65*G65/100 -> 8.9578053 | R65: =IF(OR(H65="", H66="", Q65=0), "", IF(H65<H66, (H66-H65)/H65, "")) | S65: 9.1840126 | T65: =S65-Q65 -> 0.22620721 | U65: CEMTS +0,31 | V65: =IFERROR(VLOOKUP(LEFT(U66,FIND(" ",U66)-1),'BTA Tarama'!$A:$K,11,0),"") | X65: =IF(COUNTIF('Yıldız Liste'!A:A, A65)>0, "Yıldız Pazar", IF(COUNTIF('Ana Pazar Liste'!A:A, A65)>0, "Ana Pazar", IF(COUNTIF('Alt Pazar Liste'!A:A, A65)>0, "Alt Pazar", ""))) -> Ana Pazar
A66: OZSUB | B66: Tarım Ormancılık ve Balıkçılık | C66: 1225783772 | D66: 120000000 | E66: =VLOOKUP(A66,'Tüm - Sektör'!$A:$H,5,0) -> 21.587028 | F66: =VLOOKUP(A66,'Tüm - Sektör'!$A:$H,6,0) -> 4.0884523 | G66: =VLOOKUP(A66,'Tüm - Sektör'!$A:$H,7,0) -> 42.238092 | H66: 43.88 | I66: =VLOOKUP(A66,'Tüm - Sektör'!$A:$H,9,0) -> #REF! | J66: =VLOOKUP(A66,'Tüm - Sektör'!$A:$H,10,0) -> #REF! | K66: =VLOOKUP(A66,'Tüm - Sektör'!$A:$H,11,0) -> #REF! | L66: =VLOOKUP(A66,'Tüm - Sektör'!$A:$H,12,0) -> #REF! | M66: =VLOOKUP(A66,'Tüm - Sektör'!$A:$H,13,0) -> #REF! | N66: =VLOOKUP(A66,'Tüm - Sektör'!$A:$H,14,0) -> #REF! | O66: =VLOOKUP(A66,'Tüm - Sektör'!$A:$H,15,0) -> #REF! | P66: =VLOOKUP(A66,'Tüm - Sektör'!$A:$H,16,0) -> #REF! | Q66: =E66*G66/100 -> 9.1179488 | R66: =IF(OR(H66="", H67="", Q66=0), "", IF(H66<H67, (H67-H66)/H66, "")) | S66: 9.2187925 | T66: =S66-Q66 -> 0.10084367 | U66: BIOEN +0,30 | V66: =IFERROR(VLOOKUP(LEFT(U67,FIND(" ",U67)-1),'BTA Tarama'!$A:$K,11,0),"") | X66: =IF(COUNTIF('Yıldız Liste'!A:A, A66)>0, "Yıldız Pazar", IF(COUNTIF('Ana Pazar Liste'!A:A, A66)>0, "Ana Pazar", IF(COUNTIF('Alt Pazar Liste'!A:A, A66)>0, "Alt Pazar", ""))) -> Ana Pazar
A67: ERCB | B67: Ana Metal Sanayi | C67: 5927165415 | D67: 77770481 | E67: =VLOOKUP(A67,'Tüm - Sektör'!$A:$H,5,0) -> 28.715245 | F67: =VLOOKUP(A67,'Tüm - Sektör'!$A:$H,6,0) -> 8.0267531 | G67: =VLOOKUP(A67,'Tüm - Sektör'!$A:$H,7,0) -> 31.848394 | H67: 43.74 | I67: =VLOOKUP(A67,'Tüm - Sektör'!$A:$H,9,0) -> #REF! | J67: =VLOOKUP(A67,'Tüm - Sektör'!$A:$H,10,0) -> #REF! | K67: =VLOOKUP(A67,'Tüm - Sektör'!$A:$H,11,0) -> #REF! | L67: =VLOOKUP(A67,'Tüm - Sektör'!$A:$H,12,0) -> #REF! | M67: =VLOOKUP(A67,'Tüm - Sektör'!$A:$H,13,0) -> #REF! | N67: =VLOOKUP(A67,'Tüm - Sektör'!$A:$H,14,0) -> #REF! | O67: =VLOOKUP(A67,'Tüm - Sektör'!$A:$H,15,0) -> #REF! | P67: =VLOOKUP(A67,'Tüm - Sektör'!$A:$H,16,0) -> #REF! | Q67: =E67*G67/100 -> 9.1453443 | R67: =IF(OR(H67="", H68="", Q67=0), "", IF(H67<H68, (H68-H67)/H67, "")) | S67: 8.8695645 | T67: =S67-Q67 -> -0.27577978 | U67: AEFES +0,30 | V67: =IFERROR(VLOOKUP(LEFT(U68,FIND(" ",U68)-1),'BTA Tarama'!$A:$K,11,0),"") | X67: =IF(COUNTIF('Yıldız Liste'!A:A, A67)>0, "Yıldız Pazar", IF(COUNTIF('Ana Pazar Liste'!A:A, A67)>0, "Ana Pazar", IF(COUNTIF('Alt Pazar Liste'!A:A, A67)>0, "Alt Pazar", ""))) -> Ana Pazar
A68: VSNMD | B68: Madencilik ve Tas Ocakçılığı | C68: 3913562968 | D68: 117000000 | E68: =VLOOKUP(A68,'Tüm - Sektör'!$A:$H,5,0) -> 39.129727 | F68: =VLOOKUP(A68,'Tüm - Sektör'!$A:$H,6,0) -> 7.432047 | G68: =VLOOKUP(A68,'Tüm - Sektör'!$A:$H,7,0) -> 23.988027 | H68: 42.62 | I68: =VLOOKUP(A68,'Tüm - Sektör'!$A:$H,9,0) -> #REF! | J68: =VLOOKUP(A68,'Tüm - Sektör'!$A:$H,10,0) -> #REF! | K68: =VLOOKUP(A68,'Tüm - Sektör'!$A:$H,11,0) -> #REF! | L68: =VLOOKUP(A68,'Tüm - Sektör'!$A:$H,12,0) -> #REF! | M68: =VLOOKUP(A68,'Tüm - Sektör'!$A:$H,13,0) -> #REF! | N68: =VLOOKUP(A68,'Tüm - Sektör'!$A:$H,14,0) -> #REF! | O68: =VLOOKUP(A68,'Tüm - Sektör'!$A:$H,15,0) -> #REF! | P68: =VLOOKUP(A68,'Tüm - Sektör'!$A:$H,16,0) -> #REF! | Q68: =E68*G68/100 -> 9.3864496 | R68: =IF(OR(H68="", H69="", Q68=0), "", IF(H68<H69, (H69-H68)/H68, "")) | S68: 9.2390411 | T68: =S68-Q68 -> -0.14740845 | U68: OYYAT +0,29 | V68: =IFERROR(VLOOKUP(LEFT(U69,FIND(" ",U69)-1),'BTA Tarama'!$A:$K,11,0),"") | X68: =IF(COUNTIF('Yıldız Liste'!A:A, A68)>0, "Yıldız Pazar", IF(COUNTIF('Ana Pazar Liste'!A:A, A68)>0, "Ana Pazar", IF(COUNTIF('Alt Pazar Liste'!A:A, A68)>0, "Alt Pazar", ""))) -> Ana Pazar
A69: ARTMS | B69: Tekstil , Giyim Esyası ve Deri | C69: 2429481251 | D69: 70000000 | E69: =VLOOKUP(A69,'Tüm - Sektör'!$A:$H,5,0) -> 47.684256 | F69: =VLOOKUP(A69,'Tüm - Sektör'!$A:$H,6,0) -> 17.030091 | G69: =VLOOKUP(A69,'Tüm - Sektör'!$A:$H,7,0) -> 19.831706 | H69: 42.3 | I69: =VLOOKUP(A69,'Tüm - Sektör'!$A:$H,9,0) -> #REF! | J69: =VLOOKUP(A69,'Tüm - Sektör'!$A:$H,10,0) -> #REF! | K69: =VLOOKUP(A69,'Tüm - Sektör'!$A:$H,11,0) -> #REF! | L69: =VLOOKUP(A69,'Tüm - Sektör'!$A:$H,12,0) -> #REF! | M69: =VLOOKUP(A69,'Tüm - Sektör'!$A:$H,13,0) -> #REF! | N69: =VLOOKUP(A69,'Tüm - Sektör'!$A:$H,14,0) -> #REF! | O69: =VLOOKUP(A69,'Tüm - Sektör'!$A:$H,15,0) -> #REF! | P69: =VLOOKUP(A69,'Tüm - Sektör'!$A:$H,16,0) -> #REF! | Q69: =E69*G69/100 -> 9.4566014 | R69: =IF(OR(H69="", H70="", Q69=0), "", IF(H69<H70, (H70-H69)/H69, "")) | S69: 9.9456549 | T69: =S69-Q69 -> 0.48905348 | U69: BESLR +0,29 | V69: =IFERROR(VLOOKUP(LEFT(U70,FIND(" ",U70)-1),'BTA Tarama'!$A:$K,11,0),"") | X69: =IF(COUNTIF('Yıldız Liste'!A:A, A69)>0, "Yıldız Pazar", IF(COUNTIF('Ana Pazar Liste'!A:A, A69)>0, "Ana Pazar", IF(COUNTIF('Alt Pazar Liste'!A:A, A69)>0, "Alt Pazar", ""))) -> Ana Pazar
A70: BLUME | B70: Holdingler ve Yatırım Sirketleri | C70: 620166725 | D70: 174710255 | E70: =VLOOKUP(A70,'Tüm - Sektör'!$A:$H,5,0) -> 7.383523 | F70: =VLOOKUP(A70,'Tüm - Sektör'!$A:$H,6,0) -> 1.0307691 | G70: =VLOOKUP(A70,'Tüm - Sektör'!$A:$H,7,0) -> 132.14332 | H70: 41 | I70: =VLOOKUP(A70,'Tüm - Sektör'!$A:$H,9,0) -> #REF! | J70: =VLOOKUP(A70,'Tüm - Sektör'!$A:$H,10,0) -> #REF! | K70: =VLOOKUP(A70,'Tüm - Sektör'!$A:$H,11,0) -> #REF! | L70: =VLOOKUP(A70,'Tüm - Sektör'!$A:$H,12,0) -> #REF! | M70: =VLOOKUP(A70,'Tüm - Sektör'!$A:$H,13,0) -> #REF! | N70: =VLOOKUP(A70,'Tüm - Sektör'!$A:$H,14,0) -> #REF! | O70: =VLOOKUP(A70,'Tüm - Sektör'!$A:$H,15,0) -> #REF! | P70: =VLOOKUP(A70,'Tüm - Sektör'!$A:$H,16,0) -> #REF! | Q70: =E70*G70/100 -> 9.7568323 | R70: =IF(OR(H70="", H71="", Q70=0), "", IF(H70<H71, (H71-H70)/H70, "")) | S70: 9.5518176 | T70: =S70-Q70 -> -0.20501462 | U70: AVPGY +0,28 | V70: =IFERROR(VLOOKUP(LEFT(U71,FIND(" ",U71)-1),'BTA Tarama'!$A:$K,11,0),"") | X70: =IF(COUNTIF('Yıldız Liste'!A:A, A70)>0, "Yıldız Pazar", IF(COUNTIF('Ana Pazar Liste'!A:A, A70)>0, "Ana Pazar", IF(COUNTIF('Alt Pazar Liste'!A:A, A70)>0, "Alt Pazar", ""))) -> Ana Pazar
A71: PNLSN | B71: Ana Metal Sanayi | C71: 3231285211 | D71: 75000000 | E71: =VLOOKUP(A71,'Tüm - Sektör'!$A:$H,5,0) -> 46.8253 | F71: =VLOOKUP(A71,'Tüm - Sektör'!$A:$H,6,0) -> 14.865175 | G71: =VLOOKUP(A71,'Tüm - Sektör'!$A:$H,7,0) -> 20.950915 | H71: 40.78 | I71: =VLOOKUP(A71,'Tüm - Sektör'!$A:$H,9,0) -> #REF! | J71: =VLOOKUP(A71,'Tüm - Sektör'!$A:$H,10,0) -> #REF! | K71: =VLOOKUP(A71,'Tüm - Sektör'!$A:$H,11,0) -> #REF! | L71: =VLOOKUP(A71,'Tüm - Sektör'!$A:$H,12,0) -> #REF! | M71: =VLOOKUP(A71,'Tüm - Sektör'!$A:$H,13,0) -> #REF! | N71: =VLOOKUP(A71,'Tüm - Sektör'!$A:$H,14,0) -> #REF! | O71: =VLOOKUP(A71,'Tüm - Sektör'!$A:$H,15,0) -> #REF! | P71: =VLOOKUP(A71,'Tüm - Sektör'!$A:$H,16,0) -> #REF! | Q71: =E71*G71/100 -> 9.8103289 | R71: =IF(OR(H71="", H72="", Q71=0), "", IF(H71<H72, (H72-H71)/H71, "")) | S71: 9.7481776 | T71: =S71-Q71 -> -0.062151206 | U71: ISCTR +0,27 | V71: =IFERROR(VLOOKUP(LEFT(U72,FIND(" ",U72)-1),'BTA Tarama'!$A:$K,11,0),"") -> 124838240175 | X71: =IF(COUNTIF('Yıldız Liste'!A:A, A71)>0, "Yıldız Pazar", IF(COUNTIF('Ana Pazar Liste'!A:A, A71)>0, "Ana Pazar", IF(COUNTIF('Alt Pazar Liste'!A:A, A71)>0, "Alt Pazar", ""))) -> Ana Pazar
A72: AKHAN | B72: Gıda , İçecek ve Tütün | C72: 5199468670 | D72: 273350000 | E72: =VLOOKUP(A72,'Tüm - Sektör'!$A:$H,5,0) -> 18.174072 | F72: =VLOOKUP(A72,'Tüm - Sektör'!$A:$H,6,0) -> 1.6621614 | G72: =VLOOKUP(A72,'Tüm - Sektör'!$A:$H,7,0) -> 54.497838 | H72: 40.4 | I72: =VLOOKUP(A72,'Tüm - Sektör'!$A:$H,9,0) -> #REF! | J72: =VLOOKUP(A72,'Tüm - Sektör'!$A:$H,10,0) -> #REF! | K72: =VLOOKUP(A72,'Tüm - Sektör'!$A:$H,11,0) -> #REF! | L72: =VLOOKUP(A72,'Tüm - Sektör'!$A:$H,12,0) -> #REF! | M72: =VLOOKUP(A72,'Tüm - Sektör'!$A:$H,13,0) -> #REF! | N72: =VLOOKUP(A72,'Tüm - Sektör'!$A:$H,14,0) -> #REF! | O72: =VLOOKUP(A72,'Tüm - Sektör'!$A:$H,15,0) -> #REF! | P72: =VLOOKUP(A72,'Tüm - Sektör'!$A:$H,16,0) -> #REF! | Q72: =E72*G72/100 -> 9.9044764 | R72: =IF(OR(H72="", H73="", Q72=0), "", IF(H72<H73, (H73-H72)/H72, "")) | S72: 9.6326636 | T72: =S72-Q72 -> -0.27181279 | U72: AVGYO +0,27 | V72: =IFERROR(VLOOKUP(LEFT(U73,FIND(" ",U73)-1),'BTA Tarama'!$A:$K,11,0),"") | X72: =IF(COUNTIF('Yıldız Liste'!A:A, A72)>0, "Yıldız Pazar", IF(COUNTIF('Ana Pazar Liste'!A:A, A72)>0, "Ana Pazar", IF(COUNTIF('Alt Pazar Liste'!A:A, A72)>0, "Alt Pazar", ""))) -> Ana Pazar
A73: DESPC | B73: Teknoloji - Bilisim | C73: 418442261 | D73: 23000000 | E73: =VLOOKUP(A73,'Tüm - Sektör'!$A:$H,5,0) -> 85.631418 | F73: =VLOOKUP(A73,'Tüm - Sektör'!$A:$H,6,0) -> 90.807443 | G73: =VLOOKUP(A73,'Tüm - Sektör'!$A:$H,7,0) -> 11.696857 | H73: 39.94 | I73: =VLOOKUP(A73,'Tüm - Sektör'!$A:$H,9,0) -> #REF! | J73: =VLOOKUP(A73,'Tüm - Sektör'!$A:$H,10,0) -> #REF! | K73: =VLOOKUP(A73,'Tüm - Sektör'!$A:$H,11,0) -> #REF! | L73: =VLOOKUP(A73,'Tüm - Sektör'!$A:$H,12,0) -> #REF! | M73: =VLOOKUP(A73,'Tüm - Sektör'!$A:$H,13,0) -> #REF! | N73: =VLOOKUP(A73,'Tüm - Sektör'!$A:$H,14,0) -> #REF! | O73: =VLOOKUP(A73,'Tüm - Sektör'!$A:$H,15,0) -> #REF! | P73: =VLOOKUP(A73,'Tüm - Sektör'!$A:$H,16,0) -> #REF! | Q73: =E73*G73/100 -> 10.016185 | R73: =IF(OR(H73="", H74="", Q73=0), "", IF(H73<H74, (H74-H73)/H73, "")) | S73: 9.8339826 | T73: =S73-Q73 -> -0.18220198 | U73: ISMEN +0,26 | V73: =IFERROR(VLOOKUP(LEFT(U74,FIND(" ",U74)-1),'BTA Tarama'!$A:$K,11,0),"") | X73: =IF(COUNTIF('Yıldız Liste'!A:A, A73)>0, "Yıldız Pazar", IF(COUNTIF('Ana Pazar Liste'!A:A, A73)>0, "Ana Pazar", IF(COUNTIF('Alt Pazar Liste'!A:A, A73)>0, "Alt Pazar", ""))) -> Ana Pazar
A74: BAKAB | B74: Kağıt, Kağıt Ürünleri Basım | C74: 3080653025 | D74: 72000000 | E74: =VLOOKUP(A74,'Tüm - Sektör'!$A:$H,5,0) -> 80.778707 | F74: =VLOOKUP(A74,'Tüm - Sektör'!$A:$H,6,0) -> 28.767346 | G74: =VLOOKUP(A74,'Tüm - Sektör'!$A:$H,7,0) -> 12.606715 | H74: 39.3 | I74: =VLOOKUP(A74,'Tüm - Sektör'!$A:$H,9,0) -> #REF! | J74: =VLOOKUP(A74,'Tüm - Sektör'!$A:$H,10,0) -> #REF! | K74: =VLOOKUP(A74,'Tüm - Sektör'!$A:$H,11,0) -> #REF! | L74: =VLOOKUP(A74,'Tüm - Sektör'!$A:$H,12,0) -> #REF! | M74: =VLOOKUP(A74,'Tüm - Sektör'!$A:$H,13,0) -> #REF! | N74: =VLOOKUP(A74,'Tüm - Sektör'!$A:$H,14,0) -> #REF! | O74: =VLOOKUP(A74,'Tüm - Sektör'!$A:$H,15,0) -> #REF! | P74: =VLOOKUP(A74,'Tüm - Sektör'!$A:$H,16,0) -> #REF! | Q74: =E74*G74/100 -> 10.183541 | R74: =IF(OR(H74="", H75="", Q74=0), "", IF(H74<H75, (H75-H74)/H74, "")) | S74: 10.433086 | T74: =S74-Q74 -> 0.24954455 | U74: ENPRA +0,25 | V74: =IFERROR(VLOOKUP(LEFT(U75,FIND(" ",U75)-1),'BTA Tarama'!$A:$K,11,0),"") -> 177665552176 | X74: =IF(COUNTIF('Yıldız Liste'!A:A, A74)>0, "Yıldız Pazar", IF(COUNTIF('Ana Pazar Liste'!A:A, A74)>0, "Ana Pazar", IF(COUNTIF('Alt Pazar Liste'!A:A, A74)>0, "Alt Pazar", ""))) -> Ana Pazar
... A105: MEDTR | B105: Kimya , İlaç , Petrol , Lastik ve Plastik Ürünler | C105: 3143931773 | D105: 119000000 | E105: =VLOOKUP(A105,'Tüm - Sektör'!$A:$H,5,0) -> 64.659793 | F105: =VLOOKUP(A105,'Tüm - Sektör'!$A:$H,6,0) -> 21.734384 | G105: =VLOOKUP(A105,'Tüm - Sektör'!$A:$H,7,0) -> 24.496238 | H105: 25.26 | I105: =VLOOKUP(A105,'Tüm - Sektör'!$A:$H,9,0) -> #REF! | J105: =VLOOKUP(A105,'Tüm - Sektör'!$A:$H,10,0) -> #REF! | K105: =VLOOKUP(A105,'Tüm - Sektör'!$A:$H,11,0) -> #REF! | L105: =VLOOKUP(A105,'Tüm - Sektör'!$A:$H,12,0) -> #REF! | M105: =VLOOKUP(A105,'Tüm - Sektör'!$A:$H,13,0) -> #REF! | N105: =VLOOKUP(A105,'Tüm - Sektör'!$A:$H,14,0) -> #REF! | O105: =VLOOKUP(A105,'Tüm - Sektör'!$A:$H,15,0) -> #REF! | P105: =VLOOKUP(A105,'Tüm - Sektör'!$A:$H,16,0) -> #REF! | Q105: =E105*G105/100 -> 15.839217 | R105: =IF(OR(H105="", H106="", Q105=0), "", IF(H105<H106, (H106-H105)/H105, "")) | S105: 15.826686 | T105: =S105-Q105 -> -0.012531026 | U105: ARASE +0,13 | V105: =IFERROR(VLOOKUP(LEFT(U106,FIND(" ",U106)-1),'BTA Tarama'!$A:$K,11,0),"") -> 0 | X105: =IF(COUNTIF('Yıldız Liste'!A:A, A105)>0, "Yıldız Pazar", IF(COUNTIF('Ana Pazar Liste'!A:A, A105)>0, "Ana Pazar", IF(COUNTIF('Alt Pazar Liste'!A:A, A105)>0, "Alt Pazar", ""))) -> Ana Pazar
A106: CEOEM | B106: Güvenlik ve Sorusturma | C106: 1357332842 | D106: 535000000 | E106: =VLOOKUP(A106,'Tüm - Sektör'!$A:$H,5,0) -> 72.484479 | F106: =VLOOKUP(A106,'Tüm - Sektör'!$A:$H,6,0) -> 65.894981 | G106: =VLOOKUP(A106,'Tüm - Sektör'!$A:$H,7,0) -> 22.20019 | H106: 24.86 | I106: =VLOOKUP(A106,'Tüm - Sektör'!$A:$H,9,0) -> #REF! | J106: =VLOOKUP(A106,'Tüm - Sektör'!$A:$H,10,0) -> #REF! | K106: =VLOOKUP(A106,'Tüm - Sektör'!$A:$H,11,0) -> #REF! | L106: =VLOOKUP(A106,'Tüm - Sektör'!$A:$H,12,0) -> #REF! | M106: =VLOOKUP(A106,'Tüm - Sektör'!$A:$H,13,0) -> #REF! | N106: =VLOOKUP(A106,'Tüm - Sektör'!$A:$H,14,0) -> #REF! | O106: =VLOOKUP(A106,'Tüm - Sektör'!$A:$H,15,0) -> #REF! | P106: =VLOOKUP(A106,'Tüm - Sektör'!$A:$H,16,0) -> #REF! | Q106: =E106*G106/100 -> 16.091692 | R106: =IF(OR(H106="", H107="", Q106=0), "", IF(H106<H107, (H107-H106)/H106, "")) | S106: 15.912469 | T106: -0.12343057 | U106: ICBCT +0,13 | V106: =IFERROR(VLOOKUP(LEFT(U107,FIND(" ",U107)-1),'BTA Tarama'!$A:$K,11,0),"") -> -5051412712,5 | X106: =IF(COUNTIF('Yıldız Liste'!A:A, A106)>0, "Yıldız Pazar", IF(COUNTIF('Ana Pazar Liste'!A:A, A106)>0, "Ana Pazar", IF(COUNTIF('Alt Pazar Liste'!A:A, A106)>0, "Alt Pazar", ""))) -> Ana Pazar
A107: CELHA | B107: Ana Metal Sanayi | C107: 4404805235 | D107: 385499653 | E107: =VLOOKUP(A107,'Tüm - Sektör'!$A:$H,5,0) -> 21.834034 | F107: =VLOOKUP(A107,'Tüm - Sektör'!$A:$H,6,0) -> 2.2655308 | G107: =VLOOKUP(A107,'Tüm - Sektör'!$A:$H,7,0) -> 74.176674 | H107: 24.7 | I107: =VLOOKUP(A107,'Tüm - Sektör'!$A:$H,9,0) -> #REF! | J107: =VLOOKUP(A107,'Tüm - Sektör'!$A:$H,10,0) -> #REF! | K107: =VLOOKUP(A107,'Tüm - Sektör'!$A:$H,11,0) -> #REF! | L107: =VLOOKUP(A107,'Tüm - Sektör'!$A:$H,12,0) -> #REF! | M107: =VLOOKUP(A107,'Tüm - Sektör'!$A:$H,13,0) -> #REF! | N107: =VLOOKUP(A107,'Tüm - Sektör'!$A:$H,14,0) -> #REF! | O107: =VLOOKUP(A107,'Tüm - Sektör'!$A:$H,15,0) -> #REF! | P107: =VLOOKUP(A107,'Tüm - Sektör'!$A:$H,16,0) -> #REF! | Q107: =E107*G107/100 -> 16.19576 | R107: =IF(OR(H107="", H108="", Q107=0), "", IF(H107<H108, (H108-H107)/H107, "")) | S107: 16.288081 | T107: =S107-Q107 -> 0.092321108 | U107: CRFSA +0,13 | V107: =IFERROR(VLOOKUP(LEFT(U108,FIND(" ",U108)-1),'BTA Tarama'!$A:$K,11,0),"") -> -3751509798 | X107: =IF(COUNTIF('Yıldız Liste'!A:A, A107)>0, "Yıldız Pazar", IF(COUNTIF('Ana Pazar Liste'!A:A, A107)>0, "Ana Pazar", IF(COUNTIF('Alt Pazar Liste'!A:A, A107)>0, "Alt Pazar", ""))) -> Ana Pazar
A108: BIZIM | B108: Perakende Ticaret | C108: 130759168 | D108: 80476074 | E108: =VLOOKUP(A108,'Tüm - Sektör'!$A:$H,5,0) -> 62.302378 | F108: =VLOOKUP(A108,'Tüm - Sektör'!$A:$H,6,0) -> 32.257195 | G108: =VLOOKUP(A108,'Tüm - Sektör'!$A:$H,7,0) -> 26.361856 | H108: 24.36 | I108: =VLOOKUP(A108,'Tüm - Sektör'!$A:$H,9,0) -> #REF! | J108: =VLOOKUP(A108,'Tüm - Sektör'!$A:$H,10,0) -> #REF! | K108: =VLOOKUP(A108,'Tüm - Sektör'!$A:$H,11,0) -> #REF! | L108: =VLOOKUP(A108,'Tüm - Sektör'!$A:$H,12,0) -> #REF! | M108: =VLOOKUP(A108,'Tüm - Sektör'!$A:$H,13,0) -> #REF! | N108: =VLOOKUP(A108,'Tüm - Sektör'!$A:$H,14,0) -> #REF! | O108: =VLOOKUP(A108,'Tüm - Sektör'!$A:$H,15,0) -> #REF! | P108: =VLOOKUP(A108,'Tüm - Sektör'!$A:$H,16,0) -> #REF! | Q108: =E108*G108/100 -> 16.424063 | R108: =IF(OR(H108="", H109="", Q108=0), "", IF(H108<H109, (H109-H108)/H108, "")) | S108: 16.546327 | T108: =S108-Q108 -> 0.1222635 | U108: GEDZA +0,12 | V108: =IFERROR(VLOOKUP(LEFT(U109,FIND(" ",U109)-1),'BTA Tarama'!$A:$K,11,0),"") -> -485202706014 | X108: =IF(COUNTIF('Yıldız Liste'!A:A, A108)>0, "Yıldız Pazar", IF(COUNTIF('Ana Pazar Liste'!A:A, A108)>0, "Ana Pazar", IF(COUNTIF('Alt Pazar Liste'!A:A, A108)>0, "Alt Pazar", ""))) -> Ana Pazar
A109: ZGYO | B109: Gayrimenkul Yatırım Ortaklıkları | C109: 3157167716 | D109: 210492225 | E109: =VLOOKUP(A109,'Tüm - Sektör'!$A:$H,5,0) -> 33.422288 | F109: =VLOOKUP(A109,'Tüm - Sektör'!$A:$H,6,0) -> 5.4752268 | G109: =VLOOKUP(A109,'Tüm - Sektör'!$A:$H,7,0) -> 50.00221 | H109: 23.94 | I109: =VLOOKUP(A109,'Tüm - Sektör'!$A:$H,9,0) -> #REF! | J109: =VLOOKUP(A109,'Tüm - Sektör'!$A:$H,10,0) -> #REF! | K109: =VLOOKUP(A109,'Tüm - Sektör'!$A:$H,11,0) -> #REF! | L109: =VLOOKUP(A109,'Tüm - Sektör'!$A:$H,12,0) -> #REF! | M109: =VLOOKUP(A109,'Tüm - Sektör'!$A:$H,13,0) -> #REF! | N109: =VLOOKUP(A109,'Tüm - Sektör'!$A:$H,14,0) -> #REF! | O109: =VLOOKUP(A109,'Tüm - Sektör'!$A:$H,15,0) -> #REF! | P109: =VLOOKUP(A109,'Tüm - Sektör'!$A:$H,16,0) -> #REF! | Q109: =E109*G109/100 -> 16.711882 | R109: =IF(OR(H109="", H110="", Q109=0), "", IF(H109<H110, (H110-H109)/H109, "")) | S109: 15.052012 | T109: =S109-Q109 -> -1.6598709 | U109: BIZIM +0,12 | V109: =IFERROR(VLOOKUP(LEFT(U110,FIND(" ",U110)-1),'BTA Tarama'!$A:$K,11,0),"") | X109: =IF(COUNTIF('Yıldız Liste'!A:A, A109)>0, "Yıldız Pazar", IF(COUNTIF('Ana Pazar Liste'!A:A, A109)>0, "Ana Pazar", IF(COUNTIF('Alt Pazar Liste'!A:A, A109)>0, "Alt Pazar", ""))) -> Ana Pazar
A110: CUSAN | B110: Ana Metal Sanayi | C110: 739485696 | D110: 71250000 | E110: =VLOOKUP(A110,'Tüm - Sektör'!$A:$H,5,0) -> 91.145811 | F110: =VLOOKUP(A110,'Tüm - Sektör'!$A:$H,6,0) -> 53.301644 | G110: =VLOOKUP(A110,'Tüm - Sektör'!$A:$H,7,0) -> 18.348433 | H110: 23.92 | I110: =VLOOKUP(A110,'Tüm - Sektör'!$A:$H,9,0) -> #REF! | J110: =VLOOKUP(A110,'Tüm - Sektör'!$A:$H,10,0) -> #REF! | K110: =VLOOKUP(A110,'Tüm - Sektör'!$A:$H,11,0) -> #REF! | L110: =VLOOKUP(A110,'Tüm - Sektör'!$A:$H,12,0) -> #REF! | M110: =VLOOKUP(A110,'Tüm - Sektör'!$A:$H,13,0) -> #REF! | N110: =VLOOKUP(A110,'Tüm - Sektör'!$A:$H,14,0) -> #REF! | O110: =VLOOKUP(A110,'Tüm - Sektör'!$A:$H,15,0) -> #REF! | P110: =VLOOKUP(A110,'Tüm - Sektör'!$A:$H,16,0) -> #REF! | Q110: =E110*G110/100 -> 16.723828 | R110: =IF(OR(H110="", H111="", Q110=0), "", IF(H110<H111, (H111-H110)/H110, "")) | S110: 16.668082 | T110: =S110-Q110 -> -0.055746094 | U110: BRMEN +0,12 | V110: =IFERROR(VLOOKUP(LEFT(U111,FIND(" ",U111)-1),'BTA Tarama'!$A:$K,11,0),"") | X110: =IF(COUNTIF('Yıldız Liste'!A:A, A110)>0, "Yıldız Pazar", IF(COUNTIF('Ana Pazar Liste'!A:A, A110)>0, "Ana Pazar", IF(COUNTIF('Alt Pazar Liste'!A:A, A110)>0, "Alt Pazar", ""))) -> Ana Pazar
A111: KRONT | B111: Teknoloji - Bilisim | C111: 824789585 | D111: 171222156 | E111: =VLOOKUP(A111,'Tüm - Sektör'!$A:$H,5,0) -> 15.387322 | F111: =VLOOKUP(A111,'Tüm - Sektör'!$A:$H,6,0) -> 3.5947034 | G111: =VLOOKUP(A111,'Tüm - Sektör'!$A:$H,7,0) -> 111.57914 | H111: 23.3 | I111: =VLOOKUP(A111,'Tüm - Sektör'!$A:$H,9,0) -> #REF! | J111: =VLOOKUP(A111,'Tüm - Sektör'!$A:$H,10,0) -> #REF! | K111: =VLOOKUP(A111,'Tüm - Sektör'!$A:$H,11,0) -> #REF! | L111: =VLOOKUP(A111,'Tüm - Sektör'!$A:$H,12,0) -> #REF! | M111: =VLOOKUP(A111,'Tüm - Sektör'!$A:$H,13,0) -> #REF! | N111: =VLOOKUP(A111,'Tüm - Sektör'!$A:$H,14,0) -> #REF! | O111: =VLOOKUP(A111,'Tüm - Sektör'!$A:$H,15,0) -> #REF! | P111: =VLOOKUP(A111,'Tüm - Sektör'!$A:$H,16,0) -> #REF! | Q111: =E111*G111/100 -> 17.169041 | R111: =IF(OR(H111="", H112="", Q111=0), "", IF(H111<H112, (H112-H111)/H111, "")) | S111: 16.02719 | T111: =S111-Q111 -> -1.1418513 | U111: GMTAS +0,12 | V111: =IFERROR(VLOOKUP(LEFT(U112,FIND(" ",U112)-1),'BTA Tarama'!$A:$K,11,0),"") -> 234960945762 | X111: =IF(COUNTIF('Yıldız Liste'!A:A, A111)>0, "Yıldız Pazar", IF(COUNTIF('Ana Pazar Liste'!A:A, A111)>0, "Ana Pazar", IF(COUNTIF('Alt Pazar Liste'!A:A, A111)>0, "Alt Pazar", ""))) -> Ana Pazar
A112: DITAS | B112: Metal Esya,Makine,Elektrikli Cihazlar,Ulasım Araç | C112: 1141807084 | D112: 170000000 | E112: =VLOOKUP(A112,'Tüm - Sektör'!$A:$H,5,0) -> 31.602183 | F112: =VLOOKUP(A112,'Tüm - Sektör'!$A:$H,6,0) -> 7.7456331 | G112: =VLOOKUP(A112,'Tüm - Sektör'!$A:$H,7,0) -> 55.376739 | H112: 22.86 | I112: =VLOOKUP(A112,'Tüm - Sektör'!$A:$H,9,0) -> #REF! | J112: =VLOOKUP(A112,'Tüm - Sektör'!$A:$H,10,0) -> #REF! | K112: =VLOOKUP(A112,'Tüm - Sektör'!$A:$H,11,0) -> #REF! | L112: =VLOOKUP(A112,'Tüm - Sektör'!$A:$H,12,0) -> #REF! | M112: =VLOOKUP(A112,'Tüm - Sektör'!$A:$H,13,0) -> #REF! | N112: =VLOOKUP(A112,'Tüm - Sektör'!$A:$H,14,0) -> #REF! | O112: =VLOOKUP(A112,'Tüm - Sektör'!$A:$H,15,0) -> #REF! | P112: =VLOOKUP(A112,'Tüm - Sektör'!$A:$H,16,0) -> #REF! | Q112: =E112*G112/100 -> 17.500258 | R112: =IF(OR(H112="", H113="", Q112=0), "", IF(H112<H113, (H113-H112)/H112, "")) | S112: 16.668996 | T112: =S112-Q112 -> -0.83126228 | U112: KIMMR +0,11 | V112: =IFERROR(VLOOKUP(LEFT(U113,FIND(" ",U113)-1),'BTA Tarama'!$A:$K,11,0),"") -> 7068360638 | X112: =IF(COUNTIF('Yıldız Liste'!A:A, A112)>0, "Yıldız Pazar", IF(COUNTIF('Ana Pazar Liste'!A:A, A112)>0, "Ana Pazar", IF(COUNTIF('Alt Pazar Liste'!A:A, A112)>0, "Alt Pazar", ""))) -> Ana Pazar
A113: DOKTA | B113: Ana Metal Sanayi | C113: 6812645348 | D113: 324000000 | E113: =VLOOKUP(A113,'Tüm - Sektör'!$A:$H,5,0) -> 54.860907 | F113: =VLOOKUP(A113,'Tüm - Sektör'!$A:$H,6,0) -> 7.3619038 | G113: =VLOOKUP(A113,'Tüm - Sektör'!$A:$H,7,0) -> 32.008809 | H113: 22.8 | I113: =VLOOKUP(A113,'Tüm - Sektör'!$A:$H,9,0) -> #REF! | J113: =VLOOKUP(A113,'Tüm - Sektör'!$A:$H,10,0) -> #REF! | K113: =VLOOKUP(A113,'Tüm - Sektör'!$A:$H,11,0) -> #REF! | L113: =VLOOKUP(A113,'Tüm - Sektör'!$A:$H,12,0) -> #REF! | M113: =VLOOKUP(A113,'Tüm - Sektör'!$A:$H,13,0) -> #REF! | N113: =VLOOKUP(A113,'Tüm - Sektör'!$A:$H,14,0) -> #REF! | O113: =VLOOKUP(A113,'Tüm - Sektör'!$A:$H,15,0) -> #REF! | P113: =VLOOKUP(A113,'Tüm - Sektör'!$A:$H,16,0) -> #REF! | Q113: =E113*G113/100 -> 17.560323 | R113: =IF(OR(H113="", H114="", Q113=0), "", IF(H113<H114, (H114-H113)/H113, "")) | S113: 17.622155 | T113: =S113-Q113 -> 0.061832123 | U113: SANFM +0,11 | V113: =IFERROR(VLOOKUP(LEFT(U114,FIND(" ",U114)-1),'BTA Tarama'!$A:$K,11,0),"") | X113: =IF(COUNTIF('Yıldız Liste'!A:A, A113)>0, "Yıldız Pazar", IF(COUNTIF('Ana Pazar Liste'!A:A, A113)>0, "Ana Pazar", IF(COUNTIF('Alt Pazar Liste'!A:A, A113)>0, "Alt Pazar", ""))) -> Ana Pazar
A114: SMART | B114: Teknoloji - Bilisim | C114: 447890029 | D114: 31862500 | E114: =VLOOKUP(A114,'Tüm - Sektör'!$A:$H,5,0) -> 59.756686 | F114: =VLOOKUP(A114,'Tüm - Sektör'!$A:$H,6,0) -> 78.14396 | G114: =VLOOKUP(A114,'Tüm - Sektör'!$A:$H,7,0) -> 29.645479 | H114: 22.58 | I114: =VLOOKUP(A114,'Tüm - Sektör'!$A:$H,9,0) -> #REF! | J114: =VLOOKUP(A114,'Tüm - Sektör'!$A:$H,10,0) -> #REF! | K114: =VLOOKUP(A114,'Tüm - Sektör'!$A:$H,11,0) -> #REF! | L114: =VLOOKUP(A114,'Tüm - Sektör'!$A:$H,12,0) -> #REF! | M114: =VLOOKUP(A114,'Tüm - Sektör'!$A:$H,13,0) -> #REF! | N114: =VLOOKUP(A114,'Tüm - Sektör'!$A:$H,14,0) -> #REF! | O114: =VLOOKUP(A114,'Tüm - Sektör'!$A:$H,15,0) -> #REF! | P114: =VLOOKUP(A114,'Tüm - Sektör'!$A:$H,16,0) -> #REF! | Q114: =E114*G114/100 -> 17.715156 | R114: =IF(OR(H114="", H115="", Q114=0), "", IF(H114<H115, (H115-H114)/H114, "")) | S114: 16.978277 | T114: =S114-Q114 -> -0.7368783 | U114: CCOLA +0,11 | V114: =IFERROR(VLOOKUP(LEFT(U115,FIND(" ",U115)-1),'BTA Tarama'!$A:$K,11,0),"") | X114: =IF(COUNTIF('Yıldız Liste'!A:A, A114)>0, "Yıldız Pazar", IF(COUNTIF('Ana Pazar Liste'!A:A, A114)>0, "Ana Pazar", IF(COUNTIF('Alt Pazar Liste'!A:A, A114)>0, "Alt Pazar", ""))) -> Ana Pazar
...

Sheet Sayfa1
A1: Sembol | B1: Periyot | C1: Birim | D1: MACD TOPLAM | E1: kapanış | F1: SEKTÖR KODU | G1: NET DÖNEM KARI | H1: FIILI DOLAŞIMDAKİ PAY ADEDİ | I1: DEFTER DEGERI | J1: OZ SERMAYE | K1: ÖDENMİŞ SERMAYE | L1: PD/DD | M1: PİYASA DEĞERİ | N1: FIILI DOLAŞIMDAKİ PAY ORANI | O1: KALDIRAÃ‡ % | P1: PUAN | Q1: BEDELLİ/BEDELSİZ | R1: Skor | T1: Macd Toplam | U1: Macd Aylık | V1: RSI Günlük | W1: RSI Saatlik | X1: RSI Aylık
A2: A1CAP | B2: 60 | C2: TL | D2: -3192.1615 | E2: 7.72 | F2: Aracı Kurumlar | G2: -1049101373 | H2: 233.178.165 | I2: 13.415774 | J2: 9055647326 | K2: 675000000 | L2: 0.59631298 | M2: 5400000000 | N2: 34,54 | O2: 43.778319 | P2: 595.09196 | R2: 19.836399 | T2: -16.747573 | U2: 9.9331768 | V2: 33.074801 | W2: 52.176638 | X2: 46.834331
A3: A1YEN | B3: 60 | C3: TL | D3: -188.91528 | E3: 2.71 | F3: Elektrik , Gaz ve Su | G3: 3618440 | H3: 448.671.928 | I3: 61.374533 | J3: 3375599291 | K3: 55000000 | L3: 0.032586806 | M3: 110000000 | N3: 74,77 | O3: 22.700967 | P3: 393.5039 | Q3: %990,91 bedelsiz | R3: 13.116797 | T3: -0.84145127 | U3: 1.0945167 | V3: 49.885882 | W3: 54.069372 | X3: 50.501078
A4: AAGYO | B4: 60 | C4: TL | D4: -73322 | E4: 12.38 | F4: Gayrimenkul Yatırım Ortaklıkları | G4: 108347048 | H4: 175.896.966 | I4: 22.947327 | J4: 13661644947 | K4: 595348000 | L4: 0.52293673 | M4: 7144176000 | N4: 25,09 | O4: 21.430642 | R4: =IF(OR(H4="", H5="", Q4=0), "", IF(H4<H5, LN(H5/H4)/10, "")) | V4: 24.499245 | W4: 36.250523
A5: ACSEL | B5: 60 | C5: TL | D5: -30387.347 | E5: 114 | F5: Kimya , İlaç , Petrol , Lastik ve Plastik Ürünler | G5: 5814918 | H5: 5.182.781 | I5: 59.558735 | J5: 638570889 | K5: 10721700 | L5: 2.0148178 | M5: 1286604000 | N5: 48,33 | O5: 36.620578 | P5: 407.94619 | R5: 13.598206 | T5: -24.856968 | U5: 64.655929 | V5: 39.439553 | W5: 37.149213 | X5: 52.71259
A6: ADEL | B6: 60 | C6: TL | D6: 9882.7263 | E6: 32.88 | F6: Diğer İmalat Sanayii | G6: -35004000 | H6: 71.729.606 | I6: 4.997518 | J6: 1298730000 | K6: 259875000 | L6: 7.0034765 | M6: 9095625000 | N6: 27,60 | O6: 63.914985 | P6: 1186.6501 | R6: 39.555004 | T6: -8.9381012 | U6: -118.42889 | V6: 57.992532 | W6: 47.810198 | X6: 43.145477
A7: ADESE | B7: 60 | C7: TL | D7: -113.26488 | E7: 0.85 | F7: Gayrimenkul Faaliyetleri | G7: -245597000 | H7: 4.679.597.870 | I7: 2.7568966 | J7: 13894759000 | K7: 5040000000 | L7: 0.31557222 | M7: 4384800000 | N7: 92,84 | O7: 22.994382 | P7: 653.87617 | Q7: %400, bedelsiz | R7: 21.795872 | T7: -1.6781371 | U7: 0.36709738 | V7: 35.465538 | W7: 53.950097 | X7: 44.612068
A8: ADGYO | B8: 60 | C8: TL | D8: 19304.563 | E8: 58.3 | F8: Gayrimenkul Yatırım Ortaklıkları | G8: -113776797 | H8: 65.829.008 | I8: 29.17591 | J8: 15925799746 | K8: 545854435 | L8: 2.0564911 | M8: 32751266100 | N8: 12,05 | O8: 16.606616 | P8: 1676.0257 | R8: 55.867523 | T8: 21.651477 | V8: 52.245722 | W8: 34.417136 | X8: 57.446757
A9: AEFES | B9: 60 | C9: TL | D9: -7166.214 | E9: 18.08 | F9: Gıda , İçecek ve Tütün | G9: 4524638000 | H9: 1.931.812.445 | I9: 20.152083 | J9: 119321530000 | K9: 5921052000 | L9: 0.89320792 | M9: 106578936000 | N9: 32,62 | O9: 47.077021 | P9: 732.82411 | R9: 24.42747 | T9: 9.6284114 | U9: 17.052976 | V9: 47.991383 | W9: 31.6394 | X9: 60.577936
A10: AFYON | B10: 60 | C10: TL | D10: -148.48241 | E10: 12.54 | F10: Tas ve Toprağa Dayalı | G10: -73365961 | H10: 194.304.468 | I10: 19.163046 | J10: 7665218313 | K10: 400000000 | L10: 0.62620526 | M10: 4800000000 | N10: 48,57 | O10: 16.911376 | P10: 543.65806 | R10: 18.121935 | T10: -5.784894 | U10: 2.4936483 | V10: 41.306602 | W10: 52.591965 | X10: 46.574821
A11: AGESA | B11: 60 | C11: TL | D11: 53216.611 | E11: 264.5 | F11: Sigorta Sirketleri | G11: 2089864424 | H11: 35.803.427 | I11: 54,85 | J11: 10363411307 | K11: 0 | L11: 4,56 | M11: 45.000.000.000 | N11: 19,89 | O11: 42.089485 | P11: 3000 | R11: 100 | T11: 26.235327 | U11: 371.97023 | V11: 48.862973 | W11: 55.487723 | X11: 67.266408
A12: AGHOL | B12: 60 | C12: TL | D12: -7067.9306 | E12: 32.38 | F12: Holdingler ve Yatırım Sirketleri | G12: 6206650000 | H12: 888.701.268 | I12: 51.928031 | J12: 126462671000 | K12: 2435345000 | L12: 0.57772265 | M12: 73060350000 | N12: 36,49 | O12: 53.061317 | P12: 1092.9814 | R12: 36.432713 | T12: 15.273501 | U12: 27.612426 | V12: 56.06937 | W12: 31.216327 | X12: 60.920518
A13: AGROT | B13: 60 | C13: TL | D13: -1094.0038 | E13: 2 | F13: Tarım Ormancılık ve Balıkçılık | G13: -166416272 | H13: 958.660.172 | I13: 3.3094763 | J13: 7942743158 | K13: 2400000000 | L13: 0.60432522 | M13: 4800000000 | N13: 39,94 | O13: 23.968719 | P13: 49.396899 | Q13: %100, bedelsiz | R13: 1.6465633 | T13: -3.2895168 | V13: 35.697988 | W13: 48.870242 | X13: 43.750506
A14: AGYO | B14: 60 | C14: TL | D14: -462.4142 | E14: 7.34 | F14: Gayrimenkul Yatırım Ortaklıkları | G14: -94693699 | H14: 48.209.040 | I14: 23.850955 | J14: 6280910429 | K14: 263340000 | L14: 0.2934893 | M14: 1843380000 | N14: 18,30 | O14: 14.753633 | P14: 422.59838 | R14: 14.086613 | T14: -3.4243927 | U14: 3.1138174 | V14: 40.573058 | W14: 49.182709 | X14: 49.490477
A15: AHGAZ | B15: 60 | C15: TL | D15: 9695.3971 | E15: 38.5 | F15: Elektrik , Gaz ve Su | G15: 3203485026 | H15: 387.970.634 | I15: 21.038995 | J15: 54701388025 | K15: 2600000000 | L15: 1.8061699 | M15: 98800000000 | N15: 14,92 | O15: 65.787101 | P15: 3000 | R15: 100 | T15: 10.39947 | U15: 44.994135 | V15: 34.335747 | W15: 46.988911 | X15: 58.710835
A16: AHSGY | B16: 60 | C16: TL | D16: -5268.9013 | E16: 16.3 | F16: Gayrimenkul Yatırım Ortaklıkları | G16: -66130209 | H16: 112.720.027 | I16: 13.914753 | J16: 10039494449 | K16: 721500000 | L16: 1.293591 | M16: 12987000000 | N16: 15,62 | O16: 22.219954 | P16: 401.7208 | R16: 13.390693 | T16: -1.329322 | V16: 45.599581 | W16: 52.101497 | X16: 63.798602
A17: AKBNK | B17: 60 | C17: TL | D17: 11119.17 | E17: 71.95 | F17: Bankalar | G17: 0 | H17: 2.764.762.881 | I17: 58.187428 | J17: 302574628000 | K17: 5200000000 | L17: 1.2545665 | M17: 379600000000 | N17: 53,16 | O17: 462.14763 | P17: 1318.2939 | R17: 43.943129 | T17: -32.814578 | U17: 60.38784 | V17: 43.337712 | W17: 65.295909 | X17: 51.843757
A18: AKCNS | B18: 60 | C18: TL | D18: 20843.677 | E18: 240.1 | F18: Tas ve Toprağa Dayalı | G18: -324227000 | H18: 39.326.844 | I18: 142.10057 | J18: 27204728000 | K18: 191447000 | L18: 1.7030192 | M18: 46330174000 | N18: 20,54 | O18: 28.74887 | P18: 1734.6594 | R18: 57.821978 | T18: 229.10887 | U18: 281.74099 | V18: 65.574461 | W18: 59.985541 | X18: 72.155489
A19: AKENR | B19: 60 | C19: TL | D19: -492.86625 | E19: 10.48 | F19: Elektrik , Gaz ve Su | G19: 389489000 | H19: 184.162.025 | I19: 19.958286 | J19: 14552864000 | K19: 729164000 | L19: 0.50104502 | M19: 7291640000 | N19: 25,25 | O19: 65.824283 | P19: 491.88432 | R19: 16.396144 | T19: -5.9294694 | U19: 3.3911368 | V19: 41.101733 | W19: 52.066758 | X19: 49.100118
A20: AKFGY | B20: 60 | C20: TL | D20: -347.37636 | E20: 2.55 | F20: Gayrimenkul Yatırım Ortaklıkları | G20: 86736503 | H20: 1.726.023.676 | I20: 9.1188145 | J20: 35563376411 | K20: 3900000000 | L20: 0.21932676 | M20: 7800000000 | N20: 44,25 | O20: 27.065497 | P20: 406.41145 | R20: 13.547048 | T20: -0.64818775 | U20: 1.5997884 | V20: 36.690139 | W20: 44.904434 | X20: 52.934752
A21: AKFIS | B21: 60 | C21: TL | D21: 8808.398 | E21: 17 | F21: İnsaat ve Bayındırlık | G21: 810045000 | H21: 66.826.562 | I21: 56.040108 | J21: 35674236000 | K21: 636584000 | L21: 0.32119853 | M21: 11458512000 | N21: 10,49 | O21: 43.31209 | P21: 2301.1627 | Q21: %500, bedelsiz | R21: 76.705424 | T21: 182.48842 | V21: 54.411979 | W21: 40.191468 | X21: 88.222712
A22: AKFYE | B22: 60 | C22: TL | D22: -3165.6531 | E22: 22.78 | F22: Elektrik , Gaz ve Su | G22: 485076000 | H22: 294.010.634 | I22: 52.055791 | J22: 62308804000 | K22: 1196962000 | L22: 0.44183365 | M22: 27530126000 | N22: 24,56 | O22: 23.563855 | P22: 886.70733 | R22: 29.556911 | T22: 7.9575125 | U22: 11.803354 | V22: 43.748934 | W22: 33.16522 | X22: 59.384539
A23: AKGRT | B23: 60 | C23: TL | D23: -1532.9064 | E23: 6.17 | F23: Sigorta Sirketleri | G23: 3157815002 | H23: 451.234.908 | I23: 4,85 | J23: 7810665698 | K23: 0 | L23: 1,47 | M23: 11.477.440.000 | N23: 27,99 | O23: 63.42638 | P23: 845.01523 | R23: 28.167174 | T23: -4.2470016 | U23: 3.2905069 | V23: 26.962411 | W23: 31.0955 | X23: 48.273397
A24: AKHAN | B24: 60 | C24: TL | D24: 151214 | E24: 40.4 | F24: Gıda , İçecek ve Tütün | G24: 13511423 | H24: 54.497.838 | I24: 19.021287 | J24: 5199468670 | K24: 273350000 | L24: 2.1029072 | M24: 10934000000 | N24: 19,93 | O24: 50.381944 | R24: =IF(OR(H24="", H25="", Q24=0), "", IF(H24<H25, LN(H25/H24)/10, "")) | V24: 53.532467 | W24: 45.644684
A25: AKMGY | B25: 60 | C25: TL | D25: 45337.135 | E25: 258.5 | F25: Gayrimenkul Yatırım Ortaklıkları | G25: 25223013 | H25: 3.365.585 | I25: 283.92398 | J25: 10580143341 | K25: 37264000 | L25: 0.95448083 | M25: 10098544000 | N25: 9,03 | O25: 19.320532 | P25: 1251.2526 | R25: 41.708419 | T25: 27.842339 | U25: 171.54513 | V25: 55.577579 | W25: 44.018415 | X25: 57.465741
A26: AKSA | B26: 60 | C26: TL | D26: -3409.2013 | E26: 10.7 | F26: Kimya , İlaç , Petrol , Lastik ve Plastik Ürünler | G26: 617790000 | H26: 1.198.914.348 | I26: 8.6615763 | J26: 33650224000 | K26: 3885000000 | L26: 1.2699767 | M26: 42735000000 | N26: 30,86 | O26: 54.813733 | P26: 980.5596 | R26: 32.68532 | T26: 6.0174523 | U26: 8.2232071 | V26: 54.761123 | W26: 29.599458 | X26: 59.792942
A27: AKSEN | B27: 60 | C27: TL | D27: -32198.026 | E27: 78.55 | F27: Elektrik , Gaz ve Su | G27: 795959146 | H27: 238.538.732 | I27: 52.30414 | J27: 64142566183 | K27: 1226338236 | L27: 1.5868725 | M27: 101786073588 | N27: 19,45 | O27: 49.584664 | P27: 986.70018 | R27: 32.890006 | T27: 11.93376 | U27: 134.83351 | V27: 33.690787 | W27: 44.440157 | X27: 62.683919
A28: AKSGY | B28: 60 | C28: TL | D28: 1410.1655 | E28: 9.97 | F28: Gayrimenkul Yatırım Ortaklıkları | G28: 164632000 | H28: 1.289.753.751 | I28: 20.385911 | J28: 49231975000 | K28: 2415000000 | L28: 0.49053486 | M28: 24150000000 | N28: 53,40 | O28: 17.414726 | P28: 2581.8504 | R28: 86.061679 | T28: 3.5461149 | U28: 11.228601 | V28: 56.829391 | W28: 47.380842 | X28: 71.467025
A29: AKSUE | B29: 60 | C29: TL | D29: -22131.857 | E29: 30.3 | F29: Elektrik , Gaz ve Su | G29: -21593090 | H29: 53.070.769 | I29: 14.99585 | J29: 989726098 | K29: 66000000 | L29: 2.4673493 | M29: 2442000000 | N29: 80,41 | O29: 12.387574 | P29: 1013.5737 | R29: 33.78579 | T29: 55.84608 | U29: 68.645705 | V29: 53.58324 | W29: 61.554028 | X29: 77.072005
A30: AKYHO | B30: 60 | C30: TL | D30: -579.74225 | E30: 2.06 | F30: Holdingler ve Yatırım Sirketleri | G30: -24015799 | H30: 192.870.518 | I30: 2.6163825 | J30: 659872586 | K30: 252208000 | L30: 0.76441424 | M30: 504416000 | N30: 77,71 | O30: 14.838191 | P30: 404.63731 | R30: 13.48791 | T30: -2.4073526 | U30: -3.4264242 | V30: 35.175366 | W30: 47.818664 | X30: 40.499917
A31: ALARK | B31: 60 | C31: TL | D31: 13893.035 | E31: 107.9 | F31: Holdingler ve Yatırım Sirketleri | G31: 116650000 | H31: 143.017.654 | I31: 189.23298 | J31: 82316348000 | K31: 435000000 | L31: 0.58129401 | M31: 47850000000 | N31: 34,29 | O31: 35.711426 | P31: 1923.2367 | R31: 64.107888 | T31: 26.723118 | U31: 44.311302 | V31: 52.595048 | W31: 41.442327 | X31: 55.351331
A32: ALBRK | B32: 60 | C32: TL | D32: 1857.7095 | E32: 8.68 | F32: Bankalar | G32: 0 | H32: 1.007.169.114 | I32: 10,23 | J32: 29439691000 | K32: 0 | L32: 0,83 | M32: 21.250.000.000 | N32: 40,28 | O32: 347.93631 | P32: 2129.0792 | R32: 70.969308 | T32: -0.78756876 | U32: 7.7816913 | V32: 51.397619 | W32: 54.677961 | X32: 58.311492
A33: ALCAR | B33: 60 | C33: TL | D33: -225806.34 | E33: 671 | F33: Metal Esya,Makine,Elektrikli Cihazlar,Ulasım Araç | G33: -67675452 | H33: 1.717.981 | I33: 188.25807 | J33: 2033187111 | K33: 10800000 | L33: 3.6917409 | M33: 7506000000 | N33: 15,90 | O33: 65.324546 | P33: 164.59701 | R33: 5.4865672 | T33: -449.49961 | U33: -513.16366 | V33: 39.84727 | W33: 45.076966 | X33: 41.92919
A34: ALCTL | B34: 60 | C34: TL | D34: -111146.84 | E34: 116.1 | F34: Teknoloji - Bilisim | G34: -6595639 | H34: 13.534.167 | I34: 86.244615 | J34: 3337733172 | K34: 38700772 | L34: 1.3913912 | M34: 4644092640 | N34: 34,97 | O34: 45.162762 | P34: 656.86064 | R34: 21.895355 | T34: 50.474506 | U34: 148.86008 | V34: 36.747551 | W34: 21.977141 | X34: 54.896984
A35: ALFAS | B35: 60 | C35: TL | D35: -9151.6752 | E35: 40 | F35: Elektrik , Gaz ve Su | G35: 48198916 | H35: 84.545.682 | I35: 15.956985 | J35: 5872170565 | K35: 368000000 | L35: 2.5694077 | M35: 15088000000 | N35: 22,97 | O35: 54.967135 | P35: 204.43746 | R35: 6.8145819 | T35: -22.489224 | U35: -60.485455 | V35: 34.611213 | W35: 37.904985 | X35: 46.921299
A36: ALGYO | B36: 60 | C36: TL | D36: -3.01121 | E36: 3.62 | F36: Gayrimenkul Yatırım Ortaklıkları | G36: 57488849 | H36: 886.891.574 | I36: 8.6681073 | J36: 17584122383 | K36: 2028600000 | L36: 0.34609632 | M36: 6085800000 | N36: 43,71 | O36: 39.09075 | P36: 424.00617 | R36: 14.133539 | T36: -7.5001579 | U36: 5.0072926 | V36: 30.959513 | W36: 51.605159 | X36: 46.234799
A37: ALKA | B37: 60 | C37: TL | D37: -1138.8926 | E37: 8.11 | F37: Kağıt, Kağıt Ürünleri Basım | G37: -78670547 | H37: 139.256.457 | I37: 3.0074751 | J37: 2210494206 | K37: 735000000 | L37: 2.6600386 | M37: 5880000000 | N37: 18,94 | O37: 41.986458 | P37: 404.83019 | R37: 13.49434 | T37: -10.604499 | U37: 6.6290221 | V37: 34.777588 | W37: 41.85251 | X37: 47.462143
A38: ALKIM | B38: 60 | C38: TL | D38: -2531.486 | E38: 15.45 | F38: Kimya , İlaç , Petrol , Lastik ve Plastik Ürünler | G38: -211813709 | H38: 140.647.705 | I38: 14.938622 | J38: 4481586649 | K38: 300000000 | L38: 1.0041087 | M38: 4500000000 | N38: 46,88 | O38: 30.458783 | P38: 423.90242 | R38: 14.130081 | T38: -12.773467 | U38: 1.5120313 | V38: 34.297022 | W38: 34.791321 | X38: 46.17822
A39: ALKLC | B39: 60 | C39: TL | D39: 80150.444 | E39: 427 | F39: Gıda , İçecek ve Tütün | G39: -54281567 | H39: 44.440.303 | I39: 25.565131 | J39: 2863294706 | K39: 112000000 | L39: 16.702437 | M39: 47824000000 | N39: 39,67 | O39: 58.752859 | P39: 2742.8364 | R39: 91.42788 | T39: 560.79916 | V39: 70.831058 | W39: 54.872931 | X39: 91.656659
A40: ALTNY | B40: 60 | C40: TL | D40: 5210.7379 | E40: 17.4 | F40: Teknoloji - Savunma | G40: -78845344 | H40: 371.308.342 | I40: 5.0341635 | J40: 5034163461 | K40: 1000000000 | L40: 3.5755692 | M40: 18000000000 | N40: 37,13 | O40: 49.203279 | P40: 1752.8115 | Q40: %325, bedelsiz | R40: 58.42705 | T40: -1.7537611 | V40: 49.287006 | W40: 69.091097 | X40: 45.990593
...

Sheet Takip Listesi
A1: HİSSE | B1: Takip Fiyatı | C1: Anlık | D1: Değişim % | E1: Macd Toplam | F1: Macd Aylık | G1: Dolaşımdaki Pay% | H1: Kaldıraç % | I1: Dolaşım X | J1: Piyasa X | K1: Puan | L1: Takip Tarihi | M1: RSI Günlük | N1: RSI Saatlik | O1: RSI Aylık

Sheet Değişiklikler
A1: Kontrol tarihi | B1: 46266.03
A2: BIST'te toplam | B2: 592
A3: Sayfa1'de toplam | B3: 630
